2025-06-07 22:29:46,950:INFO:HTTP Request: GET https://api.openai.com/v1/assistants/asst_JNBneKAQp334VzhFMsdpihbP "HTTP/1.1 200 OK"
2025-06-07 22:29:47,215:INFO:HTTP Request: POST https://api.openai.com/v1/threads "HTTP/1.1 200 OK"
2025-06-07 22:29:47,218:INFO:logging in using static token
2025-06-07 22:29:48,364:INFO:Shard ID None has connected to Gateway (Session ID: a6a1c40ea0c5148bc6f6b3e61668b2ea).
2025-06-08 01:09:58,238:INFO:Shard ID None has successfully RESUMED session a6a1c40ea0c5148bc6f6b3e61668b2ea.
2025-06-08 02:25:00,417:INFO:Shard ID None has successfully RESUMED session a6a1c40ea0c5148bc6f6b3e61668b2ea.
2025-06-08 04:05:00,515:ERROR:Attempting a reconnect in 1.76s
Traceback (most recent call last):
  File "/home/imafella/Documents/Development/discord_banker_bot/.venv/lib/python3.12/site-packages/aiohttp/connector.py", line 1376, in _create_direct_connection
    hosts = await self._resolve_host(host, port, traces=traces)
            ^^^^^^^^^^^^^^^^^^^^^^^^^^^^^^^^^^^^^^^^^^^^^^^^^^^
  File "/home/imafella/Documents/Development/discord_banker_bot/.venv/lib/python3.12/site-packages/aiohttp/connector.py", line 1013, in _resolve_host
    return await asyncio.shield(resolved_host_task)
           ^^^^^^^^^^^^^^^^^^^^^^^^^^^^^^^^^^^^^^^^
  File "/home/imafella/Documents/Development/discord_banker_bot/.venv/lib/python3.12/site-packages/aiohttp/connector.py", line 1044, in _resolve_host_with_throttle
    addrs = await self._resolver.resolve(host, port, family=self._family)
            ^^^^^^^^^^^^^^^^^^^^^^^^^^^^^^^^^^^^^^^^^^^^^^^^^^^^^^^^^^^^^
  File "/home/imafella/Documents/Development/discord_banker_bot/.venv/lib/python3.12/site-packages/aiohttp/resolver.py", line 40, in resolve
    infos = await self._loop.getaddrinfo(
            ^^^^^^^^^^^^^^^^^^^^^^^^^^^^^
  File "/usr/lib/python3.12/asyncio/base_events.py", line 901, in getaddrinfo
    return await self.run_in_executor(
           ^^^^^^^^^^^^^^^^^^^^^^^^^^^
  File "/usr/lib/python3.12/concurrent/futures/thread.py", line 58, in run
    result = self.fn(*self.args, **self.kwargs)
             ^^^^^^^^^^^^^^^^^^^^^^^^^^^^^^^^^^
  File "/usr/lib/python3.12/socket.py", line 963, in getaddrinfo
    for res in _socket.getaddrinfo(host, port, family, type, proto, flags):
               ^^^^^^^^^^^^^^^^^^^^^^^^^^^^^^^^^^^^^^^^^^^^^^^^^^^^^^^^^^^
socket.gaierror: [Errno -3] Temporary failure in name resolution

The above exception was the direct cause of the following exception:

Traceback (most recent call last):
  File "/home/imafella/Documents/Development/discord_banker_bot/.venv/lib/python3.12/site-packages/discord/client.py", line 701, in connect
    self.ws = await asyncio.wait_for(coro, timeout=60.0)
              ^^^^^^^^^^^^^^^^^^^^^^^^^^^^^^^^^^^^^^^^^^
  File "/usr/lib/python3.12/asyncio/tasks.py", line 520, in wait_for
    return await fut
           ^^^^^^^^^
  File "/home/imafella/Documents/Development/discord_banker_bot/.venv/lib/python3.12/site-packages/discord/gateway.py", line 375, in from_client
    socket = await client.http.ws_connect(str(url))
             ^^^^^^^^^^^^^^^^^^^^^^^^^^^^^^^^^^^^^^
  File "/home/imafella/Documents/Development/discord_banker_bot/.venv/lib/python3.12/site-packages/discord/http.py", line 554, in ws_connect
    return await self.__session.ws_connect(url, **kwargs)
           ^^^^^^^^^^^^^^^^^^^^^^^^^^^^^^^^^^^^^^^^^^^^^^
  File "/home/imafella/Documents/Development/discord_banker_bot/.venv/lib/python3.12/site-packages/aiohttp/client.py", line 1036, in _ws_connect
    resp = await self.request(
           ^^^^^^^^^^^^^^^^^^^
  File "/home/imafella/Documents/Development/discord_banker_bot/.venv/lib/python3.12/site-packages/aiohttp/client.py", line 760, in _request
    resp = await handler(req)
           ^^^^^^^^^^^^^^^^^^
  File "/home/imafella/Documents/Development/discord_banker_bot/.venv/lib/python3.12/site-packages/aiohttp/client.py", line 715, in _connect_and_send_request
    conn = await self._connector.connect(
           ^^^^^^^^^^^^^^^^^^^^^^^^^^^^^^
  File "/home/imafella/Documents/Development/discord_banker_bot/.venv/lib/python3.12/site-packages/aiohttp/connector.py", line 561, in connect
    proto = await self._create_connection(req, traces, timeout)
            ^^^^^^^^^^^^^^^^^^^^^^^^^^^^^^^^^^^^^^^^^^^^^^^^^^^
  File "/home/imafella/Documents/Development/discord_banker_bot/.venv/lib/python3.12/site-packages/aiohttp/connector.py", line 1074, in _create_connection
    _, proto = await self._create_direct_connection(req, traces, timeout)
               ^^^^^^^^^^^^^^^^^^^^^^^^^^^^^^^^^^^^^^^^^^^^^^^^^^^^^^^^^^
  File "/home/imafella/Documents/Development/discord_banker_bot/.venv/lib/python3.12/site-packages/aiohttp/connector.py", line 1382, in _create_direct_connection
    raise ClientConnectorDNSError(req.connection_key, exc) from exc
aiohttp.client_exceptions.ClientConnectorDNSError: Cannot connect to host gateway-us-east1-b.discord.gg:443 ssl:default [Temporary failure in name resolution]
2025-06-08 04:05:02,288:ERROR:Attempting a reconnect in 2.36s
Traceback (most recent call last):
  File "/home/imafella/Documents/Development/discord_banker_bot/.venv/lib/python3.12/site-packages/aiohttp/connector.py", line 1376, in _create_direct_connection
    hosts = await self._resolve_host(host, port, traces=traces)
            ^^^^^^^^^^^^^^^^^^^^^^^^^^^^^^^^^^^^^^^^^^^^^^^^^^^
  File "/home/imafella/Documents/Development/discord_banker_bot/.venv/lib/python3.12/site-packages/aiohttp/connector.py", line 1013, in _resolve_host
    return await asyncio.shield(resolved_host_task)
           ^^^^^^^^^^^^^^^^^^^^^^^^^^^^^^^^^^^^^^^^
  File "/home/imafella/Documents/Development/discord_banker_bot/.venv/lib/python3.12/site-packages/aiohttp/connector.py", line 1044, in _resolve_host_with_throttle
    addrs = await self._resolver.resolve(host, port, family=self._family)
            ^^^^^^^^^^^^^^^^^^^^^^^^^^^^^^^^^^^^^^^^^^^^^^^^^^^^^^^^^^^^^
  File "/home/imafella/Documents/Development/discord_banker_bot/.venv/lib/python3.12/site-packages/aiohttp/resolver.py", line 40, in resolve
    infos = await self._loop.getaddrinfo(
            ^^^^^^^^^^^^^^^^^^^^^^^^^^^^^
  File "/usr/lib/python3.12/asyncio/base_events.py", line 901, in getaddrinfo
    return await self.run_in_executor(
           ^^^^^^^^^^^^^^^^^^^^^^^^^^^
  File "/usr/lib/python3.12/concurrent/futures/thread.py", line 58, in run
    result = self.fn(*self.args, **self.kwargs)
             ^^^^^^^^^^^^^^^^^^^^^^^^^^^^^^^^^^
  File "/usr/lib/python3.12/socket.py", line 963, in getaddrinfo
    for res in _socket.getaddrinfo(host, port, family, type, proto, flags):
               ^^^^^^^^^^^^^^^^^^^^^^^^^^^^^^^^^^^^^^^^^^^^^^^^^^^^^^^^^^^
socket.gaierror: [Errno -3] Temporary failure in name resolution

The above exception was the direct cause of the following exception:

Traceback (most recent call last):
  File "/home/imafella/Documents/Development/discord_banker_bot/.venv/lib/python3.12/site-packages/discord/client.py", line 701, in connect
    self.ws = await asyncio.wait_for(coro, timeout=60.0)
              ^^^^^^^^^^^^^^^^^^^^^^^^^^^^^^^^^^^^^^^^^^
  File "/usr/lib/python3.12/asyncio/tasks.py", line 520, in wait_for
    return await fut
           ^^^^^^^^^
  File "/home/imafella/Documents/Development/discord_banker_bot/.venv/lib/python3.12/site-packages/discord/gateway.py", line 375, in from_client
    socket = await client.http.ws_connect(str(url))
             ^^^^^^^^^^^^^^^^^^^^^^^^^^^^^^^^^^^^^^
  File "/home/imafella/Documents/Development/discord_banker_bot/.venv/lib/python3.12/site-packages/discord/http.py", line 554, in ws_connect
    return await self.__session.ws_connect(url, **kwargs)
           ^^^^^^^^^^^^^^^^^^^^^^^^^^^^^^^^^^^^^^^^^^^^^^
  File "/home/imafella/Documents/Development/discord_banker_bot/.venv/lib/python3.12/site-packages/aiohttp/client.py", line 1036, in _ws_connect
    resp = await self.request(
           ^^^^^^^^^^^^^^^^^^^
  File "/home/imafella/Documents/Development/discord_banker_bot/.venv/lib/python3.12/site-packages/aiohttp/client.py", line 760, in _request
    resp = await handler(req)
           ^^^^^^^^^^^^^^^^^^
  File "/home/imafella/Documents/Development/discord_banker_bot/.venv/lib/python3.12/site-packages/aiohttp/client.py", line 715, in _connect_and_send_request
    conn = await self._connector.connect(
           ^^^^^^^^^^^^^^^^^^^^^^^^^^^^^^
  File "/home/imafella/Documents/Development/discord_banker_bot/.venv/lib/python3.12/site-packages/aiohttp/connector.py", line 561, in connect
    proto = await self._create_connection(req, traces, timeout)
            ^^^^^^^^^^^^^^^^^^^^^^^^^^^^^^^^^^^^^^^^^^^^^^^^^^^
  File "/home/imafella/Documents/Development/discord_banker_bot/.venv/lib/python3.12/site-packages/aiohttp/connector.py", line 1074, in _create_connection
    _, proto = await self._create_direct_connection(req, traces, timeout)
               ^^^^^^^^^^^^^^^^^^^^^^^^^^^^^^^^^^^^^^^^^^^^^^^^^^^^^^^^^^
  File "/home/imafella/Documents/Development/discord_banker_bot/.venv/lib/python3.12/site-packages/aiohttp/connector.py", line 1382, in _create_direct_connection
    raise ClientConnectorDNSError(req.connection_key, exc) from exc
aiohttp.client_exceptions.ClientConnectorDNSError: Cannot connect to host gateway-us-east1-b.discord.gg:443 ssl:default [Temporary failure in name resolution]
2025-06-08 04:05:04,651:ERROR:Attempting a reconnect in 3.83s
Traceback (most recent call last):
  File "/home/imafella/Documents/Development/discord_banker_bot/.venv/lib/python3.12/site-packages/aiohttp/connector.py", line 1376, in _create_direct_connection
    hosts = await self._resolve_host(host, port, traces=traces)
            ^^^^^^^^^^^^^^^^^^^^^^^^^^^^^^^^^^^^^^^^^^^^^^^^^^^
  File "/home/imafella/Documents/Development/discord_banker_bot/.venv/lib/python3.12/site-packages/aiohttp/connector.py", line 1013, in _resolve_host
    return await asyncio.shield(resolved_host_task)
           ^^^^^^^^^^^^^^^^^^^^^^^^^^^^^^^^^^^^^^^^
  File "/home/imafella/Documents/Development/discord_banker_bot/.venv/lib/python3.12/site-packages/aiohttp/connector.py", line 1044, in _resolve_host_with_throttle
    addrs = await self._resolver.resolve(host, port, family=self._family)
            ^^^^^^^^^^^^^^^^^^^^^^^^^^^^^^^^^^^^^^^^^^^^^^^^^^^^^^^^^^^^^
  File "/home/imafella/Documents/Development/discord_banker_bot/.venv/lib/python3.12/site-packages/aiohttp/resolver.py", line 40, in resolve
    infos = await self._loop.getaddrinfo(
            ^^^^^^^^^^^^^^^^^^^^^^^^^^^^^
  File "/usr/lib/python3.12/asyncio/base_events.py", line 901, in getaddrinfo
    return await self.run_in_executor(
           ^^^^^^^^^^^^^^^^^^^^^^^^^^^
  File "/usr/lib/python3.12/concurrent/futures/thread.py", line 58, in run
    result = self.fn(*self.args, **self.kwargs)
             ^^^^^^^^^^^^^^^^^^^^^^^^^^^^^^^^^^
  File "/usr/lib/python3.12/socket.py", line 963, in getaddrinfo
    for res in _socket.getaddrinfo(host, port, family, type, proto, flags):
               ^^^^^^^^^^^^^^^^^^^^^^^^^^^^^^^^^^^^^^^^^^^^^^^^^^^^^^^^^^^
socket.gaierror: [Errno -3] Temporary failure in name resolution

The above exception was the direct cause of the following exception:

Traceback (most recent call last):
  File "/home/imafella/Documents/Development/discord_banker_bot/.venv/lib/python3.12/site-packages/discord/client.py", line 701, in connect
    self.ws = await asyncio.wait_for(coro, timeout=60.0)
              ^^^^^^^^^^^^^^^^^^^^^^^^^^^^^^^^^^^^^^^^^^
  File "/usr/lib/python3.12/asyncio/tasks.py", line 520, in wait_for
    return await fut
           ^^^^^^^^^
  File "/home/imafella/Documents/Development/discord_banker_bot/.venv/lib/python3.12/site-packages/discord/gateway.py", line 375, in from_client
    socket = await client.http.ws_connect(str(url))
             ^^^^^^^^^^^^^^^^^^^^^^^^^^^^^^^^^^^^^^
  File "/home/imafella/Documents/Development/discord_banker_bot/.venv/lib/python3.12/site-packages/discord/http.py", line 554, in ws_connect
    return await self.__session.ws_connect(url, **kwargs)
           ^^^^^^^^^^^^^^^^^^^^^^^^^^^^^^^^^^^^^^^^^^^^^^
  File "/home/imafella/Documents/Development/discord_banker_bot/.venv/lib/python3.12/site-packages/aiohttp/client.py", line 1036, in _ws_connect
    resp = await self.request(
           ^^^^^^^^^^^^^^^^^^^
  File "/home/imafella/Documents/Development/discord_banker_bot/.venv/lib/python3.12/site-packages/aiohttp/client.py", line 760, in _request
    resp = await handler(req)
           ^^^^^^^^^^^^^^^^^^
  File "/home/imafella/Documents/Development/discord_banker_bot/.venv/lib/python3.12/site-packages/aiohttp/client.py", line 715, in _connect_and_send_request
    conn = await self._connector.connect(
           ^^^^^^^^^^^^^^^^^^^^^^^^^^^^^^
  File "/home/imafella/Documents/Development/discord_banker_bot/.venv/lib/python3.12/site-packages/aiohttp/connector.py", line 561, in connect
    proto = await self._create_connection(req, traces, timeout)
            ^^^^^^^^^^^^^^^^^^^^^^^^^^^^^^^^^^^^^^^^^^^^^^^^^^^
  File "/home/imafella/Documents/Development/discord_banker_bot/.venv/lib/python3.12/site-packages/aiohttp/connector.py", line 1074, in _create_connection
    _, proto = await self._create_direct_connection(req, traces, timeout)
               ^^^^^^^^^^^^^^^^^^^^^^^^^^^^^^^^^^^^^^^^^^^^^^^^^^^^^^^^^^
  File "/home/imafella/Documents/Development/discord_banker_bot/.venv/lib/python3.12/site-packages/aiohttp/connector.py", line 1382, in _create_direct_connection
    raise ClientConnectorDNSError(req.connection_key, exc) from exc
aiohttp.client_exceptions.ClientConnectorDNSError: Cannot connect to host gateway-us-east1-b.discord.gg:443 ssl:default [Temporary failure in name resolution]
2025-06-08 04:05:08,490:ERROR:Attempting a reconnect in 10.40s
Traceback (most recent call last):
  File "/home/imafella/Documents/Development/discord_banker_bot/.venv/lib/python3.12/site-packages/aiohttp/connector.py", line 1376, in _create_direct_connection
    hosts = await self._resolve_host(host, port, traces=traces)
            ^^^^^^^^^^^^^^^^^^^^^^^^^^^^^^^^^^^^^^^^^^^^^^^^^^^
  File "/home/imafella/Documents/Development/discord_banker_bot/.venv/lib/python3.12/site-packages/aiohttp/connector.py", line 1013, in _resolve_host
    return await asyncio.shield(resolved_host_task)
           ^^^^^^^^^^^^^^^^^^^^^^^^^^^^^^^^^^^^^^^^
  File "/home/imafella/Documents/Development/discord_banker_bot/.venv/lib/python3.12/site-packages/aiohttp/connector.py", line 1044, in _resolve_host_with_throttle
    addrs = await self._resolver.resolve(host, port, family=self._family)
            ^^^^^^^^^^^^^^^^^^^^^^^^^^^^^^^^^^^^^^^^^^^^^^^^^^^^^^^^^^^^^
  File "/home/imafella/Documents/Development/discord_banker_bot/.venv/lib/python3.12/site-packages/aiohttp/resolver.py", line 40, in resolve
    infos = await self._loop.getaddrinfo(
            ^^^^^^^^^^^^^^^^^^^^^^^^^^^^^
  File "/usr/lib/python3.12/asyncio/base_events.py", line 901, in getaddrinfo
    return await self.run_in_executor(
           ^^^^^^^^^^^^^^^^^^^^^^^^^^^
  File "/usr/lib/python3.12/concurrent/futures/thread.py", line 58, in run
    result = self.fn(*self.args, **self.kwargs)
             ^^^^^^^^^^^^^^^^^^^^^^^^^^^^^^^^^^
  File "/usr/lib/python3.12/socket.py", line 963, in getaddrinfo
    for res in _socket.getaddrinfo(host, port, family, type, proto, flags):
               ^^^^^^^^^^^^^^^^^^^^^^^^^^^^^^^^^^^^^^^^^^^^^^^^^^^^^^^^^^^
socket.gaierror: [Errno -3] Temporary failure in name resolution

The above exception was the direct cause of the following exception:

Traceback (most recent call last):
  File "/home/imafella/Documents/Development/discord_banker_bot/.venv/lib/python3.12/site-packages/discord/client.py", line 701, in connect
    self.ws = await asyncio.wait_for(coro, timeout=60.0)
              ^^^^^^^^^^^^^^^^^^^^^^^^^^^^^^^^^^^^^^^^^^
  File "/usr/lib/python3.12/asyncio/tasks.py", line 520, in wait_for
    return await fut
           ^^^^^^^^^
  File "/home/imafella/Documents/Development/discord_banker_bot/.venv/lib/python3.12/site-packages/discord/gateway.py", line 375, in from_client
    socket = await client.http.ws_connect(str(url))
             ^^^^^^^^^^^^^^^^^^^^^^^^^^^^^^^^^^^^^^
  File "/home/imafella/Documents/Development/discord_banker_bot/.venv/lib/python3.12/site-packages/discord/http.py", line 554, in ws_connect
    return await self.__session.ws_connect(url, **kwargs)
           ^^^^^^^^^^^^^^^^^^^^^^^^^^^^^^^^^^^^^^^^^^^^^^
  File "/home/imafella/Documents/Development/discord_banker_bot/.venv/lib/python3.12/site-packages/aiohttp/client.py", line 1036, in _ws_connect
    resp = await self.request(
           ^^^^^^^^^^^^^^^^^^^
  File "/home/imafella/Documents/Development/discord_banker_bot/.venv/lib/python3.12/site-packages/aiohttp/client.py", line 760, in _request
    resp = await handler(req)
           ^^^^^^^^^^^^^^^^^^
  File "/home/imafella/Documents/Development/discord_banker_bot/.venv/lib/python3.12/site-packages/aiohttp/client.py", line 715, in _connect_and_send_request
    conn = await self._connector.connect(
           ^^^^^^^^^^^^^^^^^^^^^^^^^^^^^^
  File "/home/imafella/Documents/Development/discord_banker_bot/.venv/lib/python3.12/site-packages/aiohttp/connector.py", line 561, in connect
    proto = await self._create_connection(req, traces, timeout)
            ^^^^^^^^^^^^^^^^^^^^^^^^^^^^^^^^^^^^^^^^^^^^^^^^^^^
  File "/home/imafella/Documents/Development/discord_banker_bot/.venv/lib/python3.12/site-packages/aiohttp/connector.py", line 1074, in _create_connection
    _, proto = await self._create_direct_connection(req, traces, timeout)
               ^^^^^^^^^^^^^^^^^^^^^^^^^^^^^^^^^^^^^^^^^^^^^^^^^^^^^^^^^^
  File "/home/imafella/Documents/Development/discord_banker_bot/.venv/lib/python3.12/site-packages/aiohttp/connector.py", line 1382, in _create_direct_connection
    raise ClientConnectorDNSError(req.connection_key, exc) from exc
aiohttp.client_exceptions.ClientConnectorDNSError: Cannot connect to host gateway-us-east1-b.discord.gg:443 ssl:default [Temporary failure in name resolution]
2025-06-08 04:05:18,907:ERROR:Attempting a reconnect in 4.45s
Traceback (most recent call last):
  File "/home/imafella/Documents/Development/discord_banker_bot/.venv/lib/python3.12/site-packages/aiohttp/connector.py", line 1376, in _create_direct_connection
    hosts = await self._resolve_host(host, port, traces=traces)
            ^^^^^^^^^^^^^^^^^^^^^^^^^^^^^^^^^^^^^^^^^^^^^^^^^^^
  File "/home/imafella/Documents/Development/discord_banker_bot/.venv/lib/python3.12/site-packages/aiohttp/connector.py", line 1013, in _resolve_host
    return await asyncio.shield(resolved_host_task)
           ^^^^^^^^^^^^^^^^^^^^^^^^^^^^^^^^^^^^^^^^
  File "/home/imafella/Documents/Development/discord_banker_bot/.venv/lib/python3.12/site-packages/aiohttp/connector.py", line 1044, in _resolve_host_with_throttle
    addrs = await self._resolver.resolve(host, port, family=self._family)
            ^^^^^^^^^^^^^^^^^^^^^^^^^^^^^^^^^^^^^^^^^^^^^^^^^^^^^^^^^^^^^
  File "/home/imafella/Documents/Development/discord_banker_bot/.venv/lib/python3.12/site-packages/aiohttp/resolver.py", line 40, in resolve
    infos = await self._loop.getaddrinfo(
            ^^^^^^^^^^^^^^^^^^^^^^^^^^^^^
  File "/usr/lib/python3.12/asyncio/base_events.py", line 901, in getaddrinfo
    return await self.run_in_executor(
           ^^^^^^^^^^^^^^^^^^^^^^^^^^^
  File "/usr/lib/python3.12/concurrent/futures/thread.py", line 58, in run
    result = self.fn(*self.args, **self.kwargs)
             ^^^^^^^^^^^^^^^^^^^^^^^^^^^^^^^^^^
  File "/usr/lib/python3.12/socket.py", line 963, in getaddrinfo
    for res in _socket.getaddrinfo(host, port, family, type, proto, flags):
               ^^^^^^^^^^^^^^^^^^^^^^^^^^^^^^^^^^^^^^^^^^^^^^^^^^^^^^^^^^^
socket.gaierror: [Errno -3] Temporary failure in name resolution

The above exception was the direct cause of the following exception:

Traceback (most recent call last):
  File "/home/imafella/Documents/Development/discord_banker_bot/.venv/lib/python3.12/site-packages/discord/client.py", line 701, in connect
    self.ws = await asyncio.wait_for(coro, timeout=60.0)
              ^^^^^^^^^^^^^^^^^^^^^^^^^^^^^^^^^^^^^^^^^^
  File "/usr/lib/python3.12/asyncio/tasks.py", line 520, in wait_for
    return await fut
           ^^^^^^^^^
  File "/home/imafella/Documents/Development/discord_banker_bot/.venv/lib/python3.12/site-packages/discord/gateway.py", line 375, in from_client
    socket = await client.http.ws_connect(str(url))
             ^^^^^^^^^^^^^^^^^^^^^^^^^^^^^^^^^^^^^^
  File "/home/imafella/Documents/Development/discord_banker_bot/.venv/lib/python3.12/site-packages/discord/http.py", line 554, in ws_connect
    return await self.__session.ws_connect(url, **kwargs)
           ^^^^^^^^^^^^^^^^^^^^^^^^^^^^^^^^^^^^^^^^^^^^^^
  File "/home/imafella/Documents/Development/discord_banker_bot/.venv/lib/python3.12/site-packages/aiohttp/client.py", line 1036, in _ws_connect
    resp = await self.request(
           ^^^^^^^^^^^^^^^^^^^
  File "/home/imafella/Documents/Development/discord_banker_bot/.venv/lib/python3.12/site-packages/aiohttp/client.py", line 760, in _request
    resp = await handler(req)
           ^^^^^^^^^^^^^^^^^^
  File "/home/imafella/Documents/Development/discord_banker_bot/.venv/lib/python3.12/site-packages/aiohttp/client.py", line 715, in _connect_and_send_request
    conn = await self._connector.connect(
           ^^^^^^^^^^^^^^^^^^^^^^^^^^^^^^
  File "/home/imafella/Documents/Development/discord_banker_bot/.venv/lib/python3.12/site-packages/aiohttp/connector.py", line 561, in connect
    proto = await self._create_connection(req, traces, timeout)
            ^^^^^^^^^^^^^^^^^^^^^^^^^^^^^^^^^^^^^^^^^^^^^^^^^^^
  File "/home/imafella/Documents/Development/discord_banker_bot/.venv/lib/python3.12/site-packages/aiohttp/connector.py", line 1074, in _create_connection
    _, proto = await self._create_direct_connection(req, traces, timeout)
               ^^^^^^^^^^^^^^^^^^^^^^^^^^^^^^^^^^^^^^^^^^^^^^^^^^^^^^^^^^
  File "/home/imafella/Documents/Development/discord_banker_bot/.venv/lib/python3.12/site-packages/aiohttp/connector.py", line 1382, in _create_direct_connection
    raise ClientConnectorDNSError(req.connection_key, exc) from exc
aiohttp.client_exceptions.ClientConnectorDNSError: Cannot connect to host gateway-us-east1-b.discord.gg:443 ssl:default [Temporary failure in name resolution]
2025-06-08 04:05:23,372:ERROR:Attempting a reconnect in 35.06s
Traceback (most recent call last):
  File "/home/imafella/Documents/Development/discord_banker_bot/.venv/lib/python3.12/site-packages/aiohttp/connector.py", line 1376, in _create_direct_connection
    hosts = await self._resolve_host(host, port, traces=traces)
            ^^^^^^^^^^^^^^^^^^^^^^^^^^^^^^^^^^^^^^^^^^^^^^^^^^^
  File "/home/imafella/Documents/Development/discord_banker_bot/.venv/lib/python3.12/site-packages/aiohttp/connector.py", line 1013, in _resolve_host
    return await asyncio.shield(resolved_host_task)
           ^^^^^^^^^^^^^^^^^^^^^^^^^^^^^^^^^^^^^^^^
  File "/home/imafella/Documents/Development/discord_banker_bot/.venv/lib/python3.12/site-packages/aiohttp/connector.py", line 1044, in _resolve_host_with_throttle
    addrs = await self._resolver.resolve(host, port, family=self._family)
            ^^^^^^^^^^^^^^^^^^^^^^^^^^^^^^^^^^^^^^^^^^^^^^^^^^^^^^^^^^^^^
  File "/home/imafella/Documents/Development/discord_banker_bot/.venv/lib/python3.12/site-packages/aiohttp/resolver.py", line 40, in resolve
    infos = await self._loop.getaddrinfo(
            ^^^^^^^^^^^^^^^^^^^^^^^^^^^^^
  File "/usr/lib/python3.12/asyncio/base_events.py", line 901, in getaddrinfo
    return await self.run_in_executor(
           ^^^^^^^^^^^^^^^^^^^^^^^^^^^
  File "/usr/lib/python3.12/concurrent/futures/thread.py", line 58, in run
    result = self.fn(*self.args, **self.kwargs)
             ^^^^^^^^^^^^^^^^^^^^^^^^^^^^^^^^^^
  File "/usr/lib/python3.12/socket.py", line 963, in getaddrinfo
    for res in _socket.getaddrinfo(host, port, family, type, proto, flags):
               ^^^^^^^^^^^^^^^^^^^^^^^^^^^^^^^^^^^^^^^^^^^^^^^^^^^^^^^^^^^
socket.gaierror: [Errno -3] Temporary failure in name resolution

The above exception was the direct cause of the following exception:

Traceback (most recent call last):
  File "/home/imafella/Documents/Development/discord_banker_bot/.venv/lib/python3.12/site-packages/discord/client.py", line 701, in connect
    self.ws = await asyncio.wait_for(coro, timeout=60.0)
              ^^^^^^^^^^^^^^^^^^^^^^^^^^^^^^^^^^^^^^^^^^
  File "/usr/lib/python3.12/asyncio/tasks.py", line 520, in wait_for
    return await fut
           ^^^^^^^^^
  File "/home/imafella/Documents/Development/discord_banker_bot/.venv/lib/python3.12/site-packages/discord/gateway.py", line 375, in from_client
    socket = await client.http.ws_connect(str(url))
             ^^^^^^^^^^^^^^^^^^^^^^^^^^^^^^^^^^^^^^
  File "/home/imafella/Documents/Development/discord_banker_bot/.venv/lib/python3.12/site-packages/discord/http.py", line 554, in ws_connect
    return await self.__session.ws_connect(url, **kwargs)
           ^^^^^^^^^^^^^^^^^^^^^^^^^^^^^^^^^^^^^^^^^^^^^^
  File "/home/imafella/Documents/Development/discord_banker_bot/.venv/lib/python3.12/site-packages/aiohttp/client.py", line 1036, in _ws_connect
    resp = await self.request(
           ^^^^^^^^^^^^^^^^^^^
  File "/home/imafella/Documents/Development/discord_banker_bot/.venv/lib/python3.12/site-packages/aiohttp/client.py", line 760, in _request
    resp = await handler(req)
           ^^^^^^^^^^^^^^^^^^
  File "/home/imafella/Documents/Development/discord_banker_bot/.venv/lib/python3.12/site-packages/aiohttp/client.py", line 715, in _connect_and_send_request
    conn = await self._connector.connect(
           ^^^^^^^^^^^^^^^^^^^^^^^^^^^^^^
  File "/home/imafella/Documents/Development/discord_banker_bot/.venv/lib/python3.12/site-packages/aiohttp/connector.py", line 561, in connect
    proto = await self._create_connection(req, traces, timeout)
            ^^^^^^^^^^^^^^^^^^^^^^^^^^^^^^^^^^^^^^^^^^^^^^^^^^^
  File "/home/imafella/Documents/Development/discord_banker_bot/.venv/lib/python3.12/site-packages/aiohttp/connector.py", line 1074, in _create_connection
    _, proto = await self._create_direct_connection(req, traces, timeout)
               ^^^^^^^^^^^^^^^^^^^^^^^^^^^^^^^^^^^^^^^^^^^^^^^^^^^^^^^^^^
  File "/home/imafella/Documents/Development/discord_banker_bot/.venv/lib/python3.12/site-packages/aiohttp/connector.py", line 1382, in _create_direct_connection
    raise ClientConnectorDNSError(req.connection_key, exc) from exc
aiohttp.client_exceptions.ClientConnectorDNSError: Cannot connect to host gateway-us-east1-b.discord.gg:443 ssl:default [Temporary failure in name resolution]
2025-06-08 04:05:58,444:ERROR:Attempting a reconnect in 38.28s
Traceback (most recent call last):
  File "/home/imafella/Documents/Development/discord_banker_bot/.venv/lib/python3.12/site-packages/aiohttp/connector.py", line 1376, in _create_direct_connection
    hosts = await self._resolve_host(host, port, traces=traces)
            ^^^^^^^^^^^^^^^^^^^^^^^^^^^^^^^^^^^^^^^^^^^^^^^^^^^
  File "/home/imafella/Documents/Development/discord_banker_bot/.venv/lib/python3.12/site-packages/aiohttp/connector.py", line 1013, in _resolve_host
    return await asyncio.shield(resolved_host_task)
           ^^^^^^^^^^^^^^^^^^^^^^^^^^^^^^^^^^^^^^^^
  File "/home/imafella/Documents/Development/discord_banker_bot/.venv/lib/python3.12/site-packages/aiohttp/connector.py", line 1044, in _resolve_host_with_throttle
    addrs = await self._resolver.resolve(host, port, family=self._family)
            ^^^^^^^^^^^^^^^^^^^^^^^^^^^^^^^^^^^^^^^^^^^^^^^^^^^^^^^^^^^^^
  File "/home/imafella/Documents/Development/discord_banker_bot/.venv/lib/python3.12/site-packages/aiohttp/resolver.py", line 40, in resolve
    infos = await self._loop.getaddrinfo(
            ^^^^^^^^^^^^^^^^^^^^^^^^^^^^^
  File "/usr/lib/python3.12/asyncio/base_events.py", line 901, in getaddrinfo
    return await self.run_in_executor(
           ^^^^^^^^^^^^^^^^^^^^^^^^^^^
  File "/usr/lib/python3.12/concurrent/futures/thread.py", line 58, in run
    result = self.fn(*self.args, **self.kwargs)
             ^^^^^^^^^^^^^^^^^^^^^^^^^^^^^^^^^^
  File "/usr/lib/python3.12/socket.py", line 963, in getaddrinfo
    for res in _socket.getaddrinfo(host, port, family, type, proto, flags):
               ^^^^^^^^^^^^^^^^^^^^^^^^^^^^^^^^^^^^^^^^^^^^^^^^^^^^^^^^^^^
socket.gaierror: [Errno -3] Temporary failure in name resolution

The above exception was the direct cause of the following exception:

Traceback (most recent call last):
  File "/home/imafella/Documents/Development/discord_banker_bot/.venv/lib/python3.12/site-packages/discord/client.py", line 701, in connect
    self.ws = await asyncio.wait_for(coro, timeout=60.0)
              ^^^^^^^^^^^^^^^^^^^^^^^^^^^^^^^^^^^^^^^^^^
  File "/usr/lib/python3.12/asyncio/tasks.py", line 520, in wait_for
    return await fut
           ^^^^^^^^^
  File "/home/imafella/Documents/Development/discord_banker_bot/.venv/lib/python3.12/site-packages/discord/gateway.py", line 375, in from_client
    socket = await client.http.ws_connect(str(url))
             ^^^^^^^^^^^^^^^^^^^^^^^^^^^^^^^^^^^^^^
  File "/home/imafella/Documents/Development/discord_banker_bot/.venv/lib/python3.12/site-packages/discord/http.py", line 554, in ws_connect
    return await self.__session.ws_connect(url, **kwargs)
           ^^^^^^^^^^^^^^^^^^^^^^^^^^^^^^^^^^^^^^^^^^^^^^
  File "/home/imafella/Documents/Development/discord_banker_bot/.venv/lib/python3.12/site-packages/aiohttp/client.py", line 1036, in _ws_connect
    resp = await self.request(
           ^^^^^^^^^^^^^^^^^^^
  File "/home/imafella/Documents/Development/discord_banker_bot/.venv/lib/python3.12/site-packages/aiohttp/client.py", line 760, in _request
    resp = await handler(req)
           ^^^^^^^^^^^^^^^^^^
  File "/home/imafella/Documents/Development/discord_banker_bot/.venv/lib/python3.12/site-packages/aiohttp/client.py", line 715, in _connect_and_send_request
    conn = await self._connector.connect(
           ^^^^^^^^^^^^^^^^^^^^^^^^^^^^^^
  File "/home/imafella/Documents/Development/discord_banker_bot/.venv/lib/python3.12/site-packages/aiohttp/connector.py", line 561, in connect
    proto = await self._create_connection(req, traces, timeout)
            ^^^^^^^^^^^^^^^^^^^^^^^^^^^^^^^^^^^^^^^^^^^^^^^^^^^
  File "/home/imafella/Documents/Development/discord_banker_bot/.venv/lib/python3.12/site-packages/aiohttp/connector.py", line 1074, in _create_connection
    _, proto = await self._create_direct_connection(req, traces, timeout)
               ^^^^^^^^^^^^^^^^^^^^^^^^^^^^^^^^^^^^^^^^^^^^^^^^^^^^^^^^^^
  File "/home/imafella/Documents/Development/discord_banker_bot/.venv/lib/python3.12/site-packages/aiohttp/connector.py", line 1382, in _create_direct_connection
    raise ClientConnectorDNSError(req.connection_key, exc) from exc
aiohttp.client_exceptions.ClientConnectorDNSError: Cannot connect to host gateway-us-east1-b.discord.gg:443 ssl:default [Temporary failure in name resolution]
2025-06-08 04:06:36,742:ERROR:Attempting a reconnect in 96.07s
Traceback (most recent call last):
  File "/home/imafella/Documents/Development/discord_banker_bot/.venv/lib/python3.12/site-packages/aiohttp/connector.py", line 1376, in _create_direct_connection
    hosts = await self._resolve_host(host, port, traces=traces)
            ^^^^^^^^^^^^^^^^^^^^^^^^^^^^^^^^^^^^^^^^^^^^^^^^^^^
  File "/home/imafella/Documents/Development/discord_banker_bot/.venv/lib/python3.12/site-packages/aiohttp/connector.py", line 1013, in _resolve_host
    return await asyncio.shield(resolved_host_task)
           ^^^^^^^^^^^^^^^^^^^^^^^^^^^^^^^^^^^^^^^^
  File "/home/imafella/Documents/Development/discord_banker_bot/.venv/lib/python3.12/site-packages/aiohttp/connector.py", line 1044, in _resolve_host_with_throttle
    addrs = await self._resolver.resolve(host, port, family=self._family)
            ^^^^^^^^^^^^^^^^^^^^^^^^^^^^^^^^^^^^^^^^^^^^^^^^^^^^^^^^^^^^^
  File "/home/imafella/Documents/Development/discord_banker_bot/.venv/lib/python3.12/site-packages/aiohttp/resolver.py", line 40, in resolve
    infos = await self._loop.getaddrinfo(
            ^^^^^^^^^^^^^^^^^^^^^^^^^^^^^
  File "/usr/lib/python3.12/asyncio/base_events.py", line 901, in getaddrinfo
    return await self.run_in_executor(
           ^^^^^^^^^^^^^^^^^^^^^^^^^^^
  File "/usr/lib/python3.12/concurrent/futures/thread.py", line 58, in run
    result = self.fn(*self.args, **self.kwargs)
             ^^^^^^^^^^^^^^^^^^^^^^^^^^^^^^^^^^
  File "/usr/lib/python3.12/socket.py", line 963, in getaddrinfo
    for res in _socket.getaddrinfo(host, port, family, type, proto, flags):
               ^^^^^^^^^^^^^^^^^^^^^^^^^^^^^^^^^^^^^^^^^^^^^^^^^^^^^^^^^^^
socket.gaierror: [Errno -3] Temporary failure in name resolution

The above exception was the direct cause of the following exception:

Traceback (most recent call last):
  File "/home/imafella/Documents/Development/discord_banker_bot/.venv/lib/python3.12/site-packages/discord/client.py", line 701, in connect
    self.ws = await asyncio.wait_for(coro, timeout=60.0)
              ^^^^^^^^^^^^^^^^^^^^^^^^^^^^^^^^^^^^^^^^^^
  File "/usr/lib/python3.12/asyncio/tasks.py", line 520, in wait_for
    return await fut
           ^^^^^^^^^
  File "/home/imafella/Documents/Development/discord_banker_bot/.venv/lib/python3.12/site-packages/discord/gateway.py", line 375, in from_client
    socket = await client.http.ws_connect(str(url))
             ^^^^^^^^^^^^^^^^^^^^^^^^^^^^^^^^^^^^^^
  File "/home/imafella/Documents/Development/discord_banker_bot/.venv/lib/python3.12/site-packages/discord/http.py", line 554, in ws_connect
    return await self.__session.ws_connect(url, **kwargs)
           ^^^^^^^^^^^^^^^^^^^^^^^^^^^^^^^^^^^^^^^^^^^^^^
  File "/home/imafella/Documents/Development/discord_banker_bot/.venv/lib/python3.12/site-packages/aiohttp/client.py", line 1036, in _ws_connect
    resp = await self.request(
           ^^^^^^^^^^^^^^^^^^^
  File "/home/imafella/Documents/Development/discord_banker_bot/.venv/lib/python3.12/site-packages/aiohttp/client.py", line 760, in _request
    resp = await handler(req)
           ^^^^^^^^^^^^^^^^^^
  File "/home/imafella/Documents/Development/discord_banker_bot/.venv/lib/python3.12/site-packages/aiohttp/client.py", line 715, in _connect_and_send_request
    conn = await self._connector.connect(
           ^^^^^^^^^^^^^^^^^^^^^^^^^^^^^^
  File "/home/imafella/Documents/Development/discord_banker_bot/.venv/lib/python3.12/site-packages/aiohttp/connector.py", line 561, in connect
    proto = await self._create_connection(req, traces, timeout)
            ^^^^^^^^^^^^^^^^^^^^^^^^^^^^^^^^^^^^^^^^^^^^^^^^^^^
  File "/home/imafella/Documents/Development/discord_banker_bot/.venv/lib/python3.12/site-packages/aiohttp/connector.py", line 1074, in _create_connection
    _, proto = await self._create_direct_connection(req, traces, timeout)
               ^^^^^^^^^^^^^^^^^^^^^^^^^^^^^^^^^^^^^^^^^^^^^^^^^^^^^^^^^^
  File "/home/imafella/Documents/Development/discord_banker_bot/.venv/lib/python3.12/site-packages/aiohttp/connector.py", line 1382, in _create_direct_connection
    raise ClientConnectorDNSError(req.connection_key, exc) from exc
aiohttp.client_exceptions.ClientConnectorDNSError: Cannot connect to host gateway-us-east1-b.discord.gg:443 ssl:default [Temporary failure in name resolution]
2025-06-08 04:08:13,107:INFO:Shard ID None session has been invalidated.
2025-06-08 04:08:18,462:INFO:Shard ID None has connected to Gateway (Session ID: e0dd7f1957b8a8c265a8a44575edc66e).
2025-06-08 07:34:25,537:INFO:Shard ID None has successfully RESUMED session e0dd7f1957b8a8c265a8a44575edc66e.
2025-06-08 09:47:07,135:INFO:Shard ID None has successfully RESUMED session e0dd7f1957b8a8c265a8a44575edc66e.
2025-06-08 13:42:13,055:INFO:Shard ID None has successfully RESUMED session e0dd7f1957b8a8c265a8a44575edc66e.
2025-06-08 14:36:20,706:INFO:Shard ID None has successfully RESUMED session e0dd7f1957b8a8c265a8a44575edc66e.
2025-06-08 18:04:06,023:INFO:Shard ID None has successfully RESUMED session e0dd7f1957b8a8c265a8a44575edc66e.
2025-06-08 20:15:35,969:INFO:Shard ID None has successfully RESUMED session e0dd7f1957b8a8c265a8a44575edc66e.
2025-06-08 21:42:48,289:INFO:Shard ID None has successfully RESUMED session e0dd7f1957b8a8c265a8a44575edc66e.
2025-06-08 23:16:28,075:INFO:Shard ID None has successfully RESUMED session e0dd7f1957b8a8c265a8a44575edc66e.
2025-06-08 23:49:08,666:INFO:Shard ID None has successfully RESUMED session e0dd7f1957b8a8c265a8a44575edc66e.
2025-06-09 02:13:08,070:INFO:Shard ID None has successfully RESUMED session e0dd7f1957b8a8c265a8a44575edc66e.
2025-06-09 03:06:47,708:INFO:Shard ID None has successfully RESUMED session e0dd7f1957b8a8c265a8a44575edc66e.
2025-06-09 04:04:51,527:ERROR:Attempting a reconnect in 1.08s
Traceback (most recent call last):
  File "/home/imafella/Documents/Development/discord_banker_bot/.venv/lib/python3.12/site-packages/aiohttp/connector.py", line 1376, in _create_direct_connection
    hosts = await self._resolve_host(host, port, traces=traces)
            ^^^^^^^^^^^^^^^^^^^^^^^^^^^^^^^^^^^^^^^^^^^^^^^^^^^
  File "/home/imafella/Documents/Development/discord_banker_bot/.venv/lib/python3.12/site-packages/aiohttp/connector.py", line 1013, in _resolve_host
    return await asyncio.shield(resolved_host_task)
           ^^^^^^^^^^^^^^^^^^^^^^^^^^^^^^^^^^^^^^^^
  File "/home/imafella/Documents/Development/discord_banker_bot/.venv/lib/python3.12/site-packages/aiohttp/connector.py", line 1044, in _resolve_host_with_throttle
    addrs = await self._resolver.resolve(host, port, family=self._family)
            ^^^^^^^^^^^^^^^^^^^^^^^^^^^^^^^^^^^^^^^^^^^^^^^^^^^^^^^^^^^^^
  File "/home/imafella/Documents/Development/discord_banker_bot/.venv/lib/python3.12/site-packages/aiohttp/resolver.py", line 40, in resolve
    infos = await self._loop.getaddrinfo(
            ^^^^^^^^^^^^^^^^^^^^^^^^^^^^^
  File "/usr/lib/python3.12/asyncio/base_events.py", line 901, in getaddrinfo
    return await self.run_in_executor(
           ^^^^^^^^^^^^^^^^^^^^^^^^^^^
  File "/usr/lib/python3.12/concurrent/futures/thread.py", line 58, in run
    result = self.fn(*self.args, **self.kwargs)
             ^^^^^^^^^^^^^^^^^^^^^^^^^^^^^^^^^^
  File "/usr/lib/python3.12/socket.py", line 963, in getaddrinfo
    for res in _socket.getaddrinfo(host, port, family, type, proto, flags):
               ^^^^^^^^^^^^^^^^^^^^^^^^^^^^^^^^^^^^^^^^^^^^^^^^^^^^^^^^^^^
socket.gaierror: [Errno -3] Temporary failure in name resolution

The above exception was the direct cause of the following exception:

Traceback (most recent call last):
  File "/home/imafella/Documents/Development/discord_banker_bot/.venv/lib/python3.12/site-packages/discord/client.py", line 701, in connect
    self.ws = await asyncio.wait_for(coro, timeout=60.0)
              ^^^^^^^^^^^^^^^^^^^^^^^^^^^^^^^^^^^^^^^^^^
  File "/usr/lib/python3.12/asyncio/tasks.py", line 520, in wait_for
    return await fut
           ^^^^^^^^^
  File "/home/imafella/Documents/Development/discord_banker_bot/.venv/lib/python3.12/site-packages/discord/gateway.py", line 375, in from_client
    socket = await client.http.ws_connect(str(url))
             ^^^^^^^^^^^^^^^^^^^^^^^^^^^^^^^^^^^^^^
  File "/home/imafella/Documents/Development/discord_banker_bot/.venv/lib/python3.12/site-packages/discord/http.py", line 554, in ws_connect
    return await self.__session.ws_connect(url, **kwargs)
           ^^^^^^^^^^^^^^^^^^^^^^^^^^^^^^^^^^^^^^^^^^^^^^
  File "/home/imafella/Documents/Development/discord_banker_bot/.venv/lib/python3.12/site-packages/aiohttp/client.py", line 1036, in _ws_connect
    resp = await self.request(
           ^^^^^^^^^^^^^^^^^^^
  File "/home/imafella/Documents/Development/discord_banker_bot/.venv/lib/python3.12/site-packages/aiohttp/client.py", line 760, in _request
    resp = await handler(req)
           ^^^^^^^^^^^^^^^^^^
  File "/home/imafella/Documents/Development/discord_banker_bot/.venv/lib/python3.12/site-packages/aiohttp/client.py", line 715, in _connect_and_send_request
    conn = await self._connector.connect(
           ^^^^^^^^^^^^^^^^^^^^^^^^^^^^^^
  File "/home/imafella/Documents/Development/discord_banker_bot/.venv/lib/python3.12/site-packages/aiohttp/connector.py", line 561, in connect
    proto = await self._create_connection(req, traces, timeout)
            ^^^^^^^^^^^^^^^^^^^^^^^^^^^^^^^^^^^^^^^^^^^^^^^^^^^
  File "/home/imafella/Documents/Development/discord_banker_bot/.venv/lib/python3.12/site-packages/aiohttp/connector.py", line 1074, in _create_connection
    _, proto = await self._create_direct_connection(req, traces, timeout)
               ^^^^^^^^^^^^^^^^^^^^^^^^^^^^^^^^^^^^^^^^^^^^^^^^^^^^^^^^^^
  File "/home/imafella/Documents/Development/discord_banker_bot/.venv/lib/python3.12/site-packages/aiohttp/connector.py", line 1382, in _create_direct_connection
    raise ClientConnectorDNSError(req.connection_key, exc) from exc
aiohttp.client_exceptions.ClientConnectorDNSError: Cannot connect to host gateway-us-east1-b.discord.gg:443 ssl:default [Temporary failure in name resolution]
2025-06-09 04:04:52,610:ERROR:Attempting a reconnect in 3.04s
Traceback (most recent call last):
  File "/home/imafella/Documents/Development/discord_banker_bot/.venv/lib/python3.12/site-packages/aiohttp/connector.py", line 1376, in _create_direct_connection
    hosts = await self._resolve_host(host, port, traces=traces)
            ^^^^^^^^^^^^^^^^^^^^^^^^^^^^^^^^^^^^^^^^^^^^^^^^^^^
  File "/home/imafella/Documents/Development/discord_banker_bot/.venv/lib/python3.12/site-packages/aiohttp/connector.py", line 1013, in _resolve_host
    return await asyncio.shield(resolved_host_task)
           ^^^^^^^^^^^^^^^^^^^^^^^^^^^^^^^^^^^^^^^^
  File "/home/imafella/Documents/Development/discord_banker_bot/.venv/lib/python3.12/site-packages/aiohttp/connector.py", line 1044, in _resolve_host_with_throttle
    addrs = await self._resolver.resolve(host, port, family=self._family)
            ^^^^^^^^^^^^^^^^^^^^^^^^^^^^^^^^^^^^^^^^^^^^^^^^^^^^^^^^^^^^^
  File "/home/imafella/Documents/Development/discord_banker_bot/.venv/lib/python3.12/site-packages/aiohttp/resolver.py", line 40, in resolve
    infos = await self._loop.getaddrinfo(
            ^^^^^^^^^^^^^^^^^^^^^^^^^^^^^
  File "/usr/lib/python3.12/asyncio/base_events.py", line 901, in getaddrinfo
    return await self.run_in_executor(
           ^^^^^^^^^^^^^^^^^^^^^^^^^^^
  File "/usr/lib/python3.12/concurrent/futures/thread.py", line 58, in run
    result = self.fn(*self.args, **self.kwargs)
             ^^^^^^^^^^^^^^^^^^^^^^^^^^^^^^^^^^
  File "/usr/lib/python3.12/socket.py", line 963, in getaddrinfo
    for res in _socket.getaddrinfo(host, port, family, type, proto, flags):
               ^^^^^^^^^^^^^^^^^^^^^^^^^^^^^^^^^^^^^^^^^^^^^^^^^^^^^^^^^^^
socket.gaierror: [Errno -3] Temporary failure in name resolution

The above exception was the direct cause of the following exception:

Traceback (most recent call last):
  File "/home/imafella/Documents/Development/discord_banker_bot/.venv/lib/python3.12/site-packages/discord/client.py", line 701, in connect
    self.ws = await asyncio.wait_for(coro, timeout=60.0)
              ^^^^^^^^^^^^^^^^^^^^^^^^^^^^^^^^^^^^^^^^^^
  File "/usr/lib/python3.12/asyncio/tasks.py", line 520, in wait_for
    return await fut
           ^^^^^^^^^
  File "/home/imafella/Documents/Development/discord_banker_bot/.venv/lib/python3.12/site-packages/discord/gateway.py", line 375, in from_client
    socket = await client.http.ws_connect(str(url))
             ^^^^^^^^^^^^^^^^^^^^^^^^^^^^^^^^^^^^^^
  File "/home/imafella/Documents/Development/discord_banker_bot/.venv/lib/python3.12/site-packages/discord/http.py", line 554, in ws_connect
    return await self.__session.ws_connect(url, **kwargs)
           ^^^^^^^^^^^^^^^^^^^^^^^^^^^^^^^^^^^^^^^^^^^^^^
  File "/home/imafella/Documents/Development/discord_banker_bot/.venv/lib/python3.12/site-packages/aiohttp/client.py", line 1036, in _ws_connect
    resp = await self.request(
           ^^^^^^^^^^^^^^^^^^^
  File "/home/imafella/Documents/Development/discord_banker_bot/.venv/lib/python3.12/site-packages/aiohttp/client.py", line 760, in _request
    resp = await handler(req)
           ^^^^^^^^^^^^^^^^^^
  File "/home/imafella/Documents/Development/discord_banker_bot/.venv/lib/python3.12/site-packages/aiohttp/client.py", line 715, in _connect_and_send_request
    conn = await self._connector.connect(
           ^^^^^^^^^^^^^^^^^^^^^^^^^^^^^^
  File "/home/imafella/Documents/Development/discord_banker_bot/.venv/lib/python3.12/site-packages/aiohttp/connector.py", line 561, in connect
    proto = await self._create_connection(req, traces, timeout)
            ^^^^^^^^^^^^^^^^^^^^^^^^^^^^^^^^^^^^^^^^^^^^^^^^^^^
  File "/home/imafella/Documents/Development/discord_banker_bot/.venv/lib/python3.12/site-packages/aiohttp/connector.py", line 1074, in _create_connection
    _, proto = await self._create_direct_connection(req, traces, timeout)
               ^^^^^^^^^^^^^^^^^^^^^^^^^^^^^^^^^^^^^^^^^^^^^^^^^^^^^^^^^^
  File "/home/imafella/Documents/Development/discord_banker_bot/.venv/lib/python3.12/site-packages/aiohttp/connector.py", line 1382, in _create_direct_connection
    raise ClientConnectorDNSError(req.connection_key, exc) from exc
aiohttp.client_exceptions.ClientConnectorDNSError: Cannot connect to host gateway-us-east1-b.discord.gg:443 ssl:default [Temporary failure in name resolution]
2025-06-09 04:04:55,663:ERROR:Attempting a reconnect in 6.21s
Traceback (most recent call last):
  File "/home/imafella/Documents/Development/discord_banker_bot/.venv/lib/python3.12/site-packages/aiohttp/connector.py", line 1376, in _create_direct_connection
    hosts = await self._resolve_host(host, port, traces=traces)
            ^^^^^^^^^^^^^^^^^^^^^^^^^^^^^^^^^^^^^^^^^^^^^^^^^^^
  File "/home/imafella/Documents/Development/discord_banker_bot/.venv/lib/python3.12/site-packages/aiohttp/connector.py", line 1013, in _resolve_host
    return await asyncio.shield(resolved_host_task)
           ^^^^^^^^^^^^^^^^^^^^^^^^^^^^^^^^^^^^^^^^
  File "/home/imafella/Documents/Development/discord_banker_bot/.venv/lib/python3.12/site-packages/aiohttp/connector.py", line 1044, in _resolve_host_with_throttle
    addrs = await self._resolver.resolve(host, port, family=self._family)
            ^^^^^^^^^^^^^^^^^^^^^^^^^^^^^^^^^^^^^^^^^^^^^^^^^^^^^^^^^^^^^
  File "/home/imafella/Documents/Development/discord_banker_bot/.venv/lib/python3.12/site-packages/aiohttp/resolver.py", line 40, in resolve
    infos = await self._loop.getaddrinfo(
            ^^^^^^^^^^^^^^^^^^^^^^^^^^^^^
  File "/usr/lib/python3.12/asyncio/base_events.py", line 901, in getaddrinfo
    return await self.run_in_executor(
           ^^^^^^^^^^^^^^^^^^^^^^^^^^^
  File "/usr/lib/python3.12/concurrent/futures/thread.py", line 58, in run
    result = self.fn(*self.args, **self.kwargs)
             ^^^^^^^^^^^^^^^^^^^^^^^^^^^^^^^^^^
  File "/usr/lib/python3.12/socket.py", line 963, in getaddrinfo
    for res in _socket.getaddrinfo(host, port, family, type, proto, flags):
               ^^^^^^^^^^^^^^^^^^^^^^^^^^^^^^^^^^^^^^^^^^^^^^^^^^^^^^^^^^^
socket.gaierror: [Errno -3] Temporary failure in name resolution

The above exception was the direct cause of the following exception:

Traceback (most recent call last):
  File "/home/imafella/Documents/Development/discord_banker_bot/.venv/lib/python3.12/site-packages/discord/client.py", line 701, in connect
    self.ws = await asyncio.wait_for(coro, timeout=60.0)
              ^^^^^^^^^^^^^^^^^^^^^^^^^^^^^^^^^^^^^^^^^^
  File "/usr/lib/python3.12/asyncio/tasks.py", line 520, in wait_for
    return await fut
           ^^^^^^^^^
  File "/home/imafella/Documents/Development/discord_banker_bot/.venv/lib/python3.12/site-packages/discord/gateway.py", line 375, in from_client
    socket = await client.http.ws_connect(str(url))
             ^^^^^^^^^^^^^^^^^^^^^^^^^^^^^^^^^^^^^^
  File "/home/imafella/Documents/Development/discord_banker_bot/.venv/lib/python3.12/site-packages/discord/http.py", line 554, in ws_connect
    return await self.__session.ws_connect(url, **kwargs)
           ^^^^^^^^^^^^^^^^^^^^^^^^^^^^^^^^^^^^^^^^^^^^^^
  File "/home/imafella/Documents/Development/discord_banker_bot/.venv/lib/python3.12/site-packages/aiohttp/client.py", line 1036, in _ws_connect
    resp = await self.request(
           ^^^^^^^^^^^^^^^^^^^
  File "/home/imafella/Documents/Development/discord_banker_bot/.venv/lib/python3.12/site-packages/aiohttp/client.py", line 760, in _request
    resp = await handler(req)
           ^^^^^^^^^^^^^^^^^^
  File "/home/imafella/Documents/Development/discord_banker_bot/.venv/lib/python3.12/site-packages/aiohttp/client.py", line 715, in _connect_and_send_request
    conn = await self._connector.connect(
           ^^^^^^^^^^^^^^^^^^^^^^^^^^^^^^
  File "/home/imafella/Documents/Development/discord_banker_bot/.venv/lib/python3.12/site-packages/aiohttp/connector.py", line 561, in connect
    proto = await self._create_connection(req, traces, timeout)
            ^^^^^^^^^^^^^^^^^^^^^^^^^^^^^^^^^^^^^^^^^^^^^^^^^^^
  File "/home/imafella/Documents/Development/discord_banker_bot/.venv/lib/python3.12/site-packages/aiohttp/connector.py", line 1074, in _create_connection
    _, proto = await self._create_direct_connection(req, traces, timeout)
               ^^^^^^^^^^^^^^^^^^^^^^^^^^^^^^^^^^^^^^^^^^^^^^^^^^^^^^^^^^
  File "/home/imafella/Documents/Development/discord_banker_bot/.venv/lib/python3.12/site-packages/aiohttp/connector.py", line 1382, in _create_direct_connection
    raise ClientConnectorDNSError(req.connection_key, exc) from exc
aiohttp.client_exceptions.ClientConnectorDNSError: Cannot connect to host gateway-us-east1-b.discord.gg:443 ssl:default [Temporary failure in name resolution]
2025-06-09 04:05:01,886:ERROR:Attempting a reconnect in 14.43s
Traceback (most recent call last):
  File "/home/imafella/Documents/Development/discord_banker_bot/.venv/lib/python3.12/site-packages/aiohttp/connector.py", line 1376, in _create_direct_connection
    hosts = await self._resolve_host(host, port, traces=traces)
            ^^^^^^^^^^^^^^^^^^^^^^^^^^^^^^^^^^^^^^^^^^^^^^^^^^^
  File "/home/imafella/Documents/Development/discord_banker_bot/.venv/lib/python3.12/site-packages/aiohttp/connector.py", line 1013, in _resolve_host
    return await asyncio.shield(resolved_host_task)
           ^^^^^^^^^^^^^^^^^^^^^^^^^^^^^^^^^^^^^^^^
  File "/home/imafella/Documents/Development/discord_banker_bot/.venv/lib/python3.12/site-packages/aiohttp/connector.py", line 1044, in _resolve_host_with_throttle
    addrs = await self._resolver.resolve(host, port, family=self._family)
            ^^^^^^^^^^^^^^^^^^^^^^^^^^^^^^^^^^^^^^^^^^^^^^^^^^^^^^^^^^^^^
  File "/home/imafella/Documents/Development/discord_banker_bot/.venv/lib/python3.12/site-packages/aiohttp/resolver.py", line 40, in resolve
    infos = await self._loop.getaddrinfo(
            ^^^^^^^^^^^^^^^^^^^^^^^^^^^^^
  File "/usr/lib/python3.12/asyncio/base_events.py", line 901, in getaddrinfo
    return await self.run_in_executor(
           ^^^^^^^^^^^^^^^^^^^^^^^^^^^
  File "/usr/lib/python3.12/concurrent/futures/thread.py", line 58, in run
    result = self.fn(*self.args, **self.kwargs)
             ^^^^^^^^^^^^^^^^^^^^^^^^^^^^^^^^^^
  File "/usr/lib/python3.12/socket.py", line 963, in getaddrinfo
    for res in _socket.getaddrinfo(host, port, family, type, proto, flags):
               ^^^^^^^^^^^^^^^^^^^^^^^^^^^^^^^^^^^^^^^^^^^^^^^^^^^^^^^^^^^
socket.gaierror: [Errno -3] Temporary failure in name resolution

The above exception was the direct cause of the following exception:

Traceback (most recent call last):
  File "/home/imafella/Documents/Development/discord_banker_bot/.venv/lib/python3.12/site-packages/discord/client.py", line 701, in connect
    self.ws = await asyncio.wait_for(coro, timeout=60.0)
              ^^^^^^^^^^^^^^^^^^^^^^^^^^^^^^^^^^^^^^^^^^
  File "/usr/lib/python3.12/asyncio/tasks.py", line 520, in wait_for
    return await fut
           ^^^^^^^^^
  File "/home/imafella/Documents/Development/discord_banker_bot/.venv/lib/python3.12/site-packages/discord/gateway.py", line 375, in from_client
    socket = await client.http.ws_connect(str(url))
             ^^^^^^^^^^^^^^^^^^^^^^^^^^^^^^^^^^^^^^
  File "/home/imafella/Documents/Development/discord_banker_bot/.venv/lib/python3.12/site-packages/discord/http.py", line 554, in ws_connect
    return await self.__session.ws_connect(url, **kwargs)
           ^^^^^^^^^^^^^^^^^^^^^^^^^^^^^^^^^^^^^^^^^^^^^^
  File "/home/imafella/Documents/Development/discord_banker_bot/.venv/lib/python3.12/site-packages/aiohttp/client.py", line 1036, in _ws_connect
    resp = await self.request(
           ^^^^^^^^^^^^^^^^^^^
  File "/home/imafella/Documents/Development/discord_banker_bot/.venv/lib/python3.12/site-packages/aiohttp/client.py", line 760, in _request
    resp = await handler(req)
           ^^^^^^^^^^^^^^^^^^
  File "/home/imafella/Documents/Development/discord_banker_bot/.venv/lib/python3.12/site-packages/aiohttp/client.py", line 715, in _connect_and_send_request
    conn = await self._connector.connect(
           ^^^^^^^^^^^^^^^^^^^^^^^^^^^^^^
  File "/home/imafella/Documents/Development/discord_banker_bot/.venv/lib/python3.12/site-packages/aiohttp/connector.py", line 561, in connect
    proto = await self._create_connection(req, traces, timeout)
            ^^^^^^^^^^^^^^^^^^^^^^^^^^^^^^^^^^^^^^^^^^^^^^^^^^^
  File "/home/imafella/Documents/Development/discord_banker_bot/.venv/lib/python3.12/site-packages/aiohttp/connector.py", line 1074, in _create_connection
    _, proto = await self._create_direct_connection(req, traces, timeout)
               ^^^^^^^^^^^^^^^^^^^^^^^^^^^^^^^^^^^^^^^^^^^^^^^^^^^^^^^^^^
  File "/home/imafella/Documents/Development/discord_banker_bot/.venv/lib/python3.12/site-packages/aiohttp/connector.py", line 1382, in _create_direct_connection
    raise ClientConnectorDNSError(req.connection_key, exc) from exc
aiohttp.client_exceptions.ClientConnectorDNSError: Cannot connect to host gateway-us-east1-b.discord.gg:443 ssl:default [Temporary failure in name resolution]
2025-06-09 04:05:16,323:ERROR:Attempting a reconnect in 3.82s
Traceback (most recent call last):
  File "/home/imafella/Documents/Development/discord_banker_bot/.venv/lib/python3.12/site-packages/aiohttp/connector.py", line 1376, in _create_direct_connection
    hosts = await self._resolve_host(host, port, traces=traces)
            ^^^^^^^^^^^^^^^^^^^^^^^^^^^^^^^^^^^^^^^^^^^^^^^^^^^
  File "/home/imafella/Documents/Development/discord_banker_bot/.venv/lib/python3.12/site-packages/aiohttp/connector.py", line 1013, in _resolve_host
    return await asyncio.shield(resolved_host_task)
           ^^^^^^^^^^^^^^^^^^^^^^^^^^^^^^^^^^^^^^^^
  File "/home/imafella/Documents/Development/discord_banker_bot/.venv/lib/python3.12/site-packages/aiohttp/connector.py", line 1044, in _resolve_host_with_throttle
    addrs = await self._resolver.resolve(host, port, family=self._family)
            ^^^^^^^^^^^^^^^^^^^^^^^^^^^^^^^^^^^^^^^^^^^^^^^^^^^^^^^^^^^^^
  File "/home/imafella/Documents/Development/discord_banker_bot/.venv/lib/python3.12/site-packages/aiohttp/resolver.py", line 40, in resolve
    infos = await self._loop.getaddrinfo(
            ^^^^^^^^^^^^^^^^^^^^^^^^^^^^^
  File "/usr/lib/python3.12/asyncio/base_events.py", line 901, in getaddrinfo
    return await self.run_in_executor(
           ^^^^^^^^^^^^^^^^^^^^^^^^^^^
  File "/usr/lib/python3.12/concurrent/futures/thread.py", line 58, in run
    result = self.fn(*self.args, **self.kwargs)
             ^^^^^^^^^^^^^^^^^^^^^^^^^^^^^^^^^^
  File "/usr/lib/python3.12/socket.py", line 963, in getaddrinfo
    for res in _socket.getaddrinfo(host, port, family, type, proto, flags):
               ^^^^^^^^^^^^^^^^^^^^^^^^^^^^^^^^^^^^^^^^^^^^^^^^^^^^^^^^^^^
socket.gaierror: [Errno -3] Temporary failure in name resolution

The above exception was the direct cause of the following exception:

Traceback (most recent call last):
  File "/home/imafella/Documents/Development/discord_banker_bot/.venv/lib/python3.12/site-packages/discord/client.py", line 701, in connect
    self.ws = await asyncio.wait_for(coro, timeout=60.0)
              ^^^^^^^^^^^^^^^^^^^^^^^^^^^^^^^^^^^^^^^^^^
  File "/usr/lib/python3.12/asyncio/tasks.py", line 520, in wait_for
    return await fut
           ^^^^^^^^^
  File "/home/imafella/Documents/Development/discord_banker_bot/.venv/lib/python3.12/site-packages/discord/gateway.py", line 375, in from_client
    socket = await client.http.ws_connect(str(url))
             ^^^^^^^^^^^^^^^^^^^^^^^^^^^^^^^^^^^^^^
  File "/home/imafella/Documents/Development/discord_banker_bot/.venv/lib/python3.12/site-packages/discord/http.py", line 554, in ws_connect
    return await self.__session.ws_connect(url, **kwargs)
           ^^^^^^^^^^^^^^^^^^^^^^^^^^^^^^^^^^^^^^^^^^^^^^
  File "/home/imafella/Documents/Development/discord_banker_bot/.venv/lib/python3.12/site-packages/aiohttp/client.py", line 1036, in _ws_connect
    resp = await self.request(
           ^^^^^^^^^^^^^^^^^^^
  File "/home/imafella/Documents/Development/discord_banker_bot/.venv/lib/python3.12/site-packages/aiohttp/client.py", line 760, in _request
    resp = await handler(req)
           ^^^^^^^^^^^^^^^^^^
  File "/home/imafella/Documents/Development/discord_banker_bot/.venv/lib/python3.12/site-packages/aiohttp/client.py", line 715, in _connect_and_send_request
    conn = await self._connector.connect(
           ^^^^^^^^^^^^^^^^^^^^^^^^^^^^^^
  File "/home/imafella/Documents/Development/discord_banker_bot/.venv/lib/python3.12/site-packages/aiohttp/connector.py", line 561, in connect
    proto = await self._create_connection(req, traces, timeout)
            ^^^^^^^^^^^^^^^^^^^^^^^^^^^^^^^^^^^^^^^^^^^^^^^^^^^
  File "/home/imafella/Documents/Development/discord_banker_bot/.venv/lib/python3.12/site-packages/aiohttp/connector.py", line 1074, in _create_connection
    _, proto = await self._create_direct_connection(req, traces, timeout)
               ^^^^^^^^^^^^^^^^^^^^^^^^^^^^^^^^^^^^^^^^^^^^^^^^^^^^^^^^^^
  File "/home/imafella/Documents/Development/discord_banker_bot/.venv/lib/python3.12/site-packages/aiohttp/connector.py", line 1382, in _create_direct_connection
    raise ClientConnectorDNSError(req.connection_key, exc) from exc
aiohttp.client_exceptions.ClientConnectorDNSError: Cannot connect to host gateway-us-east1-b.discord.gg:443 ssl:default [Temporary failure in name resolution]
2025-06-09 04:05:20,156:ERROR:Attempting a reconnect in 11.05s
Traceback (most recent call last):
  File "/home/imafella/Documents/Development/discord_banker_bot/.venv/lib/python3.12/site-packages/aiohttp/connector.py", line 1376, in _create_direct_connection
    hosts = await self._resolve_host(host, port, traces=traces)
            ^^^^^^^^^^^^^^^^^^^^^^^^^^^^^^^^^^^^^^^^^^^^^^^^^^^
  File "/home/imafella/Documents/Development/discord_banker_bot/.venv/lib/python3.12/site-packages/aiohttp/connector.py", line 1013, in _resolve_host
    return await asyncio.shield(resolved_host_task)
           ^^^^^^^^^^^^^^^^^^^^^^^^^^^^^^^^^^^^^^^^
  File "/home/imafella/Documents/Development/discord_banker_bot/.venv/lib/python3.12/site-packages/aiohttp/connector.py", line 1044, in _resolve_host_with_throttle
    addrs = await self._resolver.resolve(host, port, family=self._family)
            ^^^^^^^^^^^^^^^^^^^^^^^^^^^^^^^^^^^^^^^^^^^^^^^^^^^^^^^^^^^^^
  File "/home/imafella/Documents/Development/discord_banker_bot/.venv/lib/python3.12/site-packages/aiohttp/resolver.py", line 40, in resolve
    infos = await self._loop.getaddrinfo(
            ^^^^^^^^^^^^^^^^^^^^^^^^^^^^^
  File "/usr/lib/python3.12/asyncio/base_events.py", line 901, in getaddrinfo
    return await self.run_in_executor(
           ^^^^^^^^^^^^^^^^^^^^^^^^^^^
  File "/usr/lib/python3.12/concurrent/futures/thread.py", line 58, in run
    result = self.fn(*self.args, **self.kwargs)
             ^^^^^^^^^^^^^^^^^^^^^^^^^^^^^^^^^^
  File "/usr/lib/python3.12/socket.py", line 963, in getaddrinfo
    for res in _socket.getaddrinfo(host, port, family, type, proto, flags):
               ^^^^^^^^^^^^^^^^^^^^^^^^^^^^^^^^^^^^^^^^^^^^^^^^^^^^^^^^^^^
socket.gaierror: [Errno -3] Temporary failure in name resolution

The above exception was the direct cause of the following exception:

Traceback (most recent call last):
  File "/home/imafella/Documents/Development/discord_banker_bot/.venv/lib/python3.12/site-packages/discord/client.py", line 701, in connect
    self.ws = await asyncio.wait_for(coro, timeout=60.0)
              ^^^^^^^^^^^^^^^^^^^^^^^^^^^^^^^^^^^^^^^^^^
  File "/usr/lib/python3.12/asyncio/tasks.py", line 520, in wait_for
    return await fut
           ^^^^^^^^^
  File "/home/imafella/Documents/Development/discord_banker_bot/.venv/lib/python3.12/site-packages/discord/gateway.py", line 375, in from_client
    socket = await client.http.ws_connect(str(url))
             ^^^^^^^^^^^^^^^^^^^^^^^^^^^^^^^^^^^^^^
  File "/home/imafella/Documents/Development/discord_banker_bot/.venv/lib/python3.12/site-packages/discord/http.py", line 554, in ws_connect
    return await self.__session.ws_connect(url, **kwargs)
           ^^^^^^^^^^^^^^^^^^^^^^^^^^^^^^^^^^^^^^^^^^^^^^
  File "/home/imafella/Documents/Development/discord_banker_bot/.venv/lib/python3.12/site-packages/aiohttp/client.py", line 1036, in _ws_connect
    resp = await self.request(
           ^^^^^^^^^^^^^^^^^^^
  File "/home/imafella/Documents/Development/discord_banker_bot/.venv/lib/python3.12/site-packages/aiohttp/client.py", line 760, in _request
    resp = await handler(req)
           ^^^^^^^^^^^^^^^^^^
  File "/home/imafella/Documents/Development/discord_banker_bot/.venv/lib/python3.12/site-packages/aiohttp/client.py", line 715, in _connect_and_send_request
    conn = await self._connector.connect(
           ^^^^^^^^^^^^^^^^^^^^^^^^^^^^^^
  File "/home/imafella/Documents/Development/discord_banker_bot/.venv/lib/python3.12/site-packages/aiohttp/connector.py", line 561, in connect
    proto = await self._create_connection(req, traces, timeout)
            ^^^^^^^^^^^^^^^^^^^^^^^^^^^^^^^^^^^^^^^^^^^^^^^^^^^
  File "/home/imafella/Documents/Development/discord_banker_bot/.venv/lib/python3.12/site-packages/aiohttp/connector.py", line 1074, in _create_connection
    _, proto = await self._create_direct_connection(req, traces, timeout)
               ^^^^^^^^^^^^^^^^^^^^^^^^^^^^^^^^^^^^^^^^^^^^^^^^^^^^^^^^^^
  File "/home/imafella/Documents/Development/discord_banker_bot/.venv/lib/python3.12/site-packages/aiohttp/connector.py", line 1382, in _create_direct_connection
    raise ClientConnectorDNSError(req.connection_key, exc) from exc
aiohttp.client_exceptions.ClientConnectorDNSError: Cannot connect to host gateway-us-east1-b.discord.gg:443 ssl:default [Temporary failure in name resolution]
2025-06-09 04:05:31,226:ERROR:Attempting a reconnect in 69.47s
Traceback (most recent call last):
  File "/home/imafella/Documents/Development/discord_banker_bot/.venv/lib/python3.12/site-packages/aiohttp/connector.py", line 1376, in _create_direct_connection
    hosts = await self._resolve_host(host, port, traces=traces)
            ^^^^^^^^^^^^^^^^^^^^^^^^^^^^^^^^^^^^^^^^^^^^^^^^^^^
  File "/home/imafella/Documents/Development/discord_banker_bot/.venv/lib/python3.12/site-packages/aiohttp/connector.py", line 1013, in _resolve_host
    return await asyncio.shield(resolved_host_task)
           ^^^^^^^^^^^^^^^^^^^^^^^^^^^^^^^^^^^^^^^^
  File "/home/imafella/Documents/Development/discord_banker_bot/.venv/lib/python3.12/site-packages/aiohttp/connector.py", line 1044, in _resolve_host_with_throttle
    addrs = await self._resolver.resolve(host, port, family=self._family)
            ^^^^^^^^^^^^^^^^^^^^^^^^^^^^^^^^^^^^^^^^^^^^^^^^^^^^^^^^^^^^^
  File "/home/imafella/Documents/Development/discord_banker_bot/.venv/lib/python3.12/site-packages/aiohttp/resolver.py", line 40, in resolve
    infos = await self._loop.getaddrinfo(
            ^^^^^^^^^^^^^^^^^^^^^^^^^^^^^
  File "/usr/lib/python3.12/asyncio/base_events.py", line 901, in getaddrinfo
    return await self.run_in_executor(
           ^^^^^^^^^^^^^^^^^^^^^^^^^^^
  File "/usr/lib/python3.12/concurrent/futures/thread.py", line 58, in run
    result = self.fn(*self.args, **self.kwargs)
             ^^^^^^^^^^^^^^^^^^^^^^^^^^^^^^^^^^
  File "/usr/lib/python3.12/socket.py", line 963, in getaddrinfo
    for res in _socket.getaddrinfo(host, port, family, type, proto, flags):
               ^^^^^^^^^^^^^^^^^^^^^^^^^^^^^^^^^^^^^^^^^^^^^^^^^^^^^^^^^^^
socket.gaierror: [Errno -3] Temporary failure in name resolution

The above exception was the direct cause of the following exception:

Traceback (most recent call last):
  File "/home/imafella/Documents/Development/discord_banker_bot/.venv/lib/python3.12/site-packages/discord/client.py", line 701, in connect
    self.ws = await asyncio.wait_for(coro, timeout=60.0)
              ^^^^^^^^^^^^^^^^^^^^^^^^^^^^^^^^^^^^^^^^^^
  File "/usr/lib/python3.12/asyncio/tasks.py", line 520, in wait_for
    return await fut
           ^^^^^^^^^
  File "/home/imafella/Documents/Development/discord_banker_bot/.venv/lib/python3.12/site-packages/discord/gateway.py", line 375, in from_client
    socket = await client.http.ws_connect(str(url))
             ^^^^^^^^^^^^^^^^^^^^^^^^^^^^^^^^^^^^^^
  File "/home/imafella/Documents/Development/discord_banker_bot/.venv/lib/python3.12/site-packages/discord/http.py", line 554, in ws_connect
    return await self.__session.ws_connect(url, **kwargs)
           ^^^^^^^^^^^^^^^^^^^^^^^^^^^^^^^^^^^^^^^^^^^^^^
  File "/home/imafella/Documents/Development/discord_banker_bot/.venv/lib/python3.12/site-packages/aiohttp/client.py", line 1036, in _ws_connect
    resp = await self.request(
           ^^^^^^^^^^^^^^^^^^^
  File "/home/imafella/Documents/Development/discord_banker_bot/.venv/lib/python3.12/site-packages/aiohttp/client.py", line 760, in _request
    resp = await handler(req)
           ^^^^^^^^^^^^^^^^^^
  File "/home/imafella/Documents/Development/discord_banker_bot/.venv/lib/python3.12/site-packages/aiohttp/client.py", line 715, in _connect_and_send_request
    conn = await self._connector.connect(
           ^^^^^^^^^^^^^^^^^^^^^^^^^^^^^^
  File "/home/imafella/Documents/Development/discord_banker_bot/.venv/lib/python3.12/site-packages/aiohttp/connector.py", line 561, in connect
    proto = await self._create_connection(req, traces, timeout)
            ^^^^^^^^^^^^^^^^^^^^^^^^^^^^^^^^^^^^^^^^^^^^^^^^^^^
  File "/home/imafella/Documents/Development/discord_banker_bot/.venv/lib/python3.12/site-packages/aiohttp/connector.py", line 1074, in _create_connection
    _, proto = await self._create_direct_connection(req, traces, timeout)
               ^^^^^^^^^^^^^^^^^^^^^^^^^^^^^^^^^^^^^^^^^^^^^^^^^^^^^^^^^^
  File "/home/imafella/Documents/Development/discord_banker_bot/.venv/lib/python3.12/site-packages/aiohttp/connector.py", line 1382, in _create_direct_connection
    raise ClientConnectorDNSError(req.connection_key, exc) from exc
aiohttp.client_exceptions.ClientConnectorDNSError: Cannot connect to host gateway-us-east1-b.discord.gg:443 ssl:default [Temporary failure in name resolution]
2025-06-09 04:06:40,779:ERROR:Attempting a reconnect in 7.79s
Traceback (most recent call last):
  File "/home/imafella/Documents/Development/discord_banker_bot/.venv/lib/python3.12/site-packages/aiohttp/connector.py", line 1376, in _create_direct_connection
    hosts = await self._resolve_host(host, port, traces=traces)
            ^^^^^^^^^^^^^^^^^^^^^^^^^^^^^^^^^^^^^^^^^^^^^^^^^^^
  File "/home/imafella/Documents/Development/discord_banker_bot/.venv/lib/python3.12/site-packages/aiohttp/connector.py", line 1013, in _resolve_host
    return await asyncio.shield(resolved_host_task)
           ^^^^^^^^^^^^^^^^^^^^^^^^^^^^^^^^^^^^^^^^
  File "/home/imafella/Documents/Development/discord_banker_bot/.venv/lib/python3.12/site-packages/aiohttp/connector.py", line 1044, in _resolve_host_with_throttle
    addrs = await self._resolver.resolve(host, port, family=self._family)
            ^^^^^^^^^^^^^^^^^^^^^^^^^^^^^^^^^^^^^^^^^^^^^^^^^^^^^^^^^^^^^
  File "/home/imafella/Documents/Development/discord_banker_bot/.venv/lib/python3.12/site-packages/aiohttp/resolver.py", line 40, in resolve
    infos = await self._loop.getaddrinfo(
            ^^^^^^^^^^^^^^^^^^^^^^^^^^^^^
  File "/usr/lib/python3.12/asyncio/base_events.py", line 901, in getaddrinfo
    return await self.run_in_executor(
           ^^^^^^^^^^^^^^^^^^^^^^^^^^^
  File "/usr/lib/python3.12/concurrent/futures/thread.py", line 58, in run
    result = self.fn(*self.args, **self.kwargs)
             ^^^^^^^^^^^^^^^^^^^^^^^^^^^^^^^^^^
  File "/usr/lib/python3.12/socket.py", line 963, in getaddrinfo
    for res in _socket.getaddrinfo(host, port, family, type, proto, flags):
               ^^^^^^^^^^^^^^^^^^^^^^^^^^^^^^^^^^^^^^^^^^^^^^^^^^^^^^^^^^^
socket.gaierror: [Errno -3] Temporary failure in name resolution

The above exception was the direct cause of the following exception:

Traceback (most recent call last):
  File "/home/imafella/Documents/Development/discord_banker_bot/.venv/lib/python3.12/site-packages/discord/client.py", line 701, in connect
    self.ws = await asyncio.wait_for(coro, timeout=60.0)
              ^^^^^^^^^^^^^^^^^^^^^^^^^^^^^^^^^^^^^^^^^^
  File "/usr/lib/python3.12/asyncio/tasks.py", line 520, in wait_for
    return await fut
           ^^^^^^^^^
  File "/home/imafella/Documents/Development/discord_banker_bot/.venv/lib/python3.12/site-packages/discord/gateway.py", line 375, in from_client
    socket = await client.http.ws_connect(str(url))
             ^^^^^^^^^^^^^^^^^^^^^^^^^^^^^^^^^^^^^^
  File "/home/imafella/Documents/Development/discord_banker_bot/.venv/lib/python3.12/site-packages/discord/http.py", line 554, in ws_connect
    return await self.__session.ws_connect(url, **kwargs)
           ^^^^^^^^^^^^^^^^^^^^^^^^^^^^^^^^^^^^^^^^^^^^^^
  File "/home/imafella/Documents/Development/discord_banker_bot/.venv/lib/python3.12/site-packages/aiohttp/client.py", line 1036, in _ws_connect
    resp = await self.request(
           ^^^^^^^^^^^^^^^^^^^
  File "/home/imafella/Documents/Development/discord_banker_bot/.venv/lib/python3.12/site-packages/aiohttp/client.py", line 760, in _request
    resp = await handler(req)
           ^^^^^^^^^^^^^^^^^^
  File "/home/imafella/Documents/Development/discord_banker_bot/.venv/lib/python3.12/site-packages/aiohttp/client.py", line 715, in _connect_and_send_request
    conn = await self._connector.connect(
           ^^^^^^^^^^^^^^^^^^^^^^^^^^^^^^
  File "/home/imafella/Documents/Development/discord_banker_bot/.venv/lib/python3.12/site-packages/aiohttp/connector.py", line 561, in connect
    proto = await self._create_connection(req, traces, timeout)
            ^^^^^^^^^^^^^^^^^^^^^^^^^^^^^^^^^^^^^^^^^^^^^^^^^^^
  File "/home/imafella/Documents/Development/discord_banker_bot/.venv/lib/python3.12/site-packages/aiohttp/connector.py", line 1074, in _create_connection
    _, proto = await self._create_direct_connection(req, traces, timeout)
               ^^^^^^^^^^^^^^^^^^^^^^^^^^^^^^^^^^^^^^^^^^^^^^^^^^^^^^^^^^
  File "/home/imafella/Documents/Development/discord_banker_bot/.venv/lib/python3.12/site-packages/aiohttp/connector.py", line 1382, in _create_direct_connection
    raise ClientConnectorDNSError(req.connection_key, exc) from exc
aiohttp.client_exceptions.ClientConnectorDNSError: Cannot connect to host gateway-us-east1-b.discord.gg:443 ssl:default [Temporary failure in name resolution]
2025-06-09 04:06:48,845:INFO:Shard ID None session has been invalidated.
2025-06-09 04:06:54,352:INFO:Shard ID None has connected to Gateway (Session ID: dadb594c25d80e7aad6e4ec55f47bf2f).
2025-06-09 07:45:34,562:INFO:Shard ID None has successfully RESUMED session dadb594c25d80e7aad6e4ec55f47bf2f.
2025-06-09 10:25:49,946:INFO:Shard ID None has successfully RESUMED session dadb594c25d80e7aad6e4ec55f47bf2f.
2025-06-09 11:38:05,238:INFO:Shard ID None has successfully RESUMED session dadb594c25d80e7aad6e4ec55f47bf2f.
2025-06-09 15:04:28,636:INFO:Shard ID None has successfully RESUMED session dadb594c25d80e7aad6e4ec55f47bf2f.
2025-06-09 15:38:00,460:INFO:Shard ID None has successfully RESUMED session dadb594c25d80e7aad6e4ec55f47bf2f.
2025-06-09 15:39:11,255:INFO:Shard ID None has successfully RESUMED session dadb594c25d80e7aad6e4ec55f47bf2f.
2025-06-09 17:14:58,832:INFO:Shard ID None has successfully RESUMED session dadb594c25d80e7aad6e4ec55f47bf2f.
2025-06-09 20:21:25,918:INFO:Shard ID None has successfully RESUMED session dadb594c25d80e7aad6e4ec55f47bf2f.
2025-06-10 00:19:31,436:INFO:Shard ID None has successfully RESUMED session dadb594c25d80e7aad6e4ec55f47bf2f.
2025-06-10 00:38:29,801:INFO:Shard ID None has successfully RESUMED session dadb594c25d80e7aad6e4ec55f47bf2f.
2025-06-10 01:53:54,873:INFO:Shard ID None has successfully RESUMED session dadb594c25d80e7aad6e4ec55f47bf2f.
2025-06-10 04:04:51,248:ERROR:Attempting a reconnect in 1.59s
Traceback (most recent call last):
  File "/home/imafella/Documents/Development/discord_banker_bot/.venv/lib/python3.12/site-packages/aiohttp/connector.py", line 1376, in _create_direct_connection
    hosts = await self._resolve_host(host, port, traces=traces)
            ^^^^^^^^^^^^^^^^^^^^^^^^^^^^^^^^^^^^^^^^^^^^^^^^^^^
  File "/home/imafella/Documents/Development/discord_banker_bot/.venv/lib/python3.12/site-packages/aiohttp/connector.py", line 1013, in _resolve_host
    return await asyncio.shield(resolved_host_task)
           ^^^^^^^^^^^^^^^^^^^^^^^^^^^^^^^^^^^^^^^^
  File "/home/imafella/Documents/Development/discord_banker_bot/.venv/lib/python3.12/site-packages/aiohttp/connector.py", line 1044, in _resolve_host_with_throttle
    addrs = await self._resolver.resolve(host, port, family=self._family)
            ^^^^^^^^^^^^^^^^^^^^^^^^^^^^^^^^^^^^^^^^^^^^^^^^^^^^^^^^^^^^^
  File "/home/imafella/Documents/Development/discord_banker_bot/.venv/lib/python3.12/site-packages/aiohttp/resolver.py", line 40, in resolve
    infos = await self._loop.getaddrinfo(
            ^^^^^^^^^^^^^^^^^^^^^^^^^^^^^
  File "/usr/lib/python3.12/asyncio/base_events.py", line 901, in getaddrinfo
    return await self.run_in_executor(
           ^^^^^^^^^^^^^^^^^^^^^^^^^^^
  File "/usr/lib/python3.12/concurrent/futures/thread.py", line 58, in run
    result = self.fn(*self.args, **self.kwargs)
             ^^^^^^^^^^^^^^^^^^^^^^^^^^^^^^^^^^
  File "/usr/lib/python3.12/socket.py", line 963, in getaddrinfo
    for res in _socket.getaddrinfo(host, port, family, type, proto, flags):
               ^^^^^^^^^^^^^^^^^^^^^^^^^^^^^^^^^^^^^^^^^^^^^^^^^^^^^^^^^^^
socket.gaierror: [Errno -3] Temporary failure in name resolution

The above exception was the direct cause of the following exception:

Traceback (most recent call last):
  File "/home/imafella/Documents/Development/discord_banker_bot/.venv/lib/python3.12/site-packages/discord/client.py", line 701, in connect
    self.ws = await asyncio.wait_for(coro, timeout=60.0)
              ^^^^^^^^^^^^^^^^^^^^^^^^^^^^^^^^^^^^^^^^^^
  File "/usr/lib/python3.12/asyncio/tasks.py", line 520, in wait_for
    return await fut
           ^^^^^^^^^
  File "/home/imafella/Documents/Development/discord_banker_bot/.venv/lib/python3.12/site-packages/discord/gateway.py", line 375, in from_client
    socket = await client.http.ws_connect(str(url))
             ^^^^^^^^^^^^^^^^^^^^^^^^^^^^^^^^^^^^^^
  File "/home/imafella/Documents/Development/discord_banker_bot/.venv/lib/python3.12/site-packages/discord/http.py", line 554, in ws_connect
    return await self.__session.ws_connect(url, **kwargs)
           ^^^^^^^^^^^^^^^^^^^^^^^^^^^^^^^^^^^^^^^^^^^^^^
  File "/home/imafella/Documents/Development/discord_banker_bot/.venv/lib/python3.12/site-packages/aiohttp/client.py", line 1036, in _ws_connect
    resp = await self.request(
           ^^^^^^^^^^^^^^^^^^^
  File "/home/imafella/Documents/Development/discord_banker_bot/.venv/lib/python3.12/site-packages/aiohttp/client.py", line 760, in _request
    resp = await handler(req)
           ^^^^^^^^^^^^^^^^^^
  File "/home/imafella/Documents/Development/discord_banker_bot/.venv/lib/python3.12/site-packages/aiohttp/client.py", line 715, in _connect_and_send_request
    conn = await self._connector.connect(
           ^^^^^^^^^^^^^^^^^^^^^^^^^^^^^^
  File "/home/imafella/Documents/Development/discord_banker_bot/.venv/lib/python3.12/site-packages/aiohttp/connector.py", line 561, in connect
    proto = await self._create_connection(req, traces, timeout)
            ^^^^^^^^^^^^^^^^^^^^^^^^^^^^^^^^^^^^^^^^^^^^^^^^^^^
  File "/home/imafella/Documents/Development/discord_banker_bot/.venv/lib/python3.12/site-packages/aiohttp/connector.py", line 1074, in _create_connection
    _, proto = await self._create_direct_connection(req, traces, timeout)
               ^^^^^^^^^^^^^^^^^^^^^^^^^^^^^^^^^^^^^^^^^^^^^^^^^^^^^^^^^^
  File "/home/imafella/Documents/Development/discord_banker_bot/.venv/lib/python3.12/site-packages/aiohttp/connector.py", line 1382, in _create_direct_connection
    raise ClientConnectorDNSError(req.connection_key, exc) from exc
aiohttp.client_exceptions.ClientConnectorDNSError: Cannot connect to host gateway-us-east1-b.discord.gg:443 ssl:default [Temporary failure in name resolution]
2025-06-10 04:04:52,844:ERROR:Attempting a reconnect in 1.09s
Traceback (most recent call last):
  File "/home/imafella/Documents/Development/discord_banker_bot/.venv/lib/python3.12/site-packages/aiohttp/connector.py", line 1376, in _create_direct_connection
    hosts = await self._resolve_host(host, port, traces=traces)
            ^^^^^^^^^^^^^^^^^^^^^^^^^^^^^^^^^^^^^^^^^^^^^^^^^^^
  File "/home/imafella/Documents/Development/discord_banker_bot/.venv/lib/python3.12/site-packages/aiohttp/connector.py", line 1013, in _resolve_host
    return await asyncio.shield(resolved_host_task)
           ^^^^^^^^^^^^^^^^^^^^^^^^^^^^^^^^^^^^^^^^
  File "/home/imafella/Documents/Development/discord_banker_bot/.venv/lib/python3.12/site-packages/aiohttp/connector.py", line 1044, in _resolve_host_with_throttle
    addrs = await self._resolver.resolve(host, port, family=self._family)
            ^^^^^^^^^^^^^^^^^^^^^^^^^^^^^^^^^^^^^^^^^^^^^^^^^^^^^^^^^^^^^
  File "/home/imafella/Documents/Development/discord_banker_bot/.venv/lib/python3.12/site-packages/aiohttp/resolver.py", line 40, in resolve
    infos = await self._loop.getaddrinfo(
            ^^^^^^^^^^^^^^^^^^^^^^^^^^^^^
  File "/usr/lib/python3.12/asyncio/base_events.py", line 901, in getaddrinfo
    return await self.run_in_executor(
           ^^^^^^^^^^^^^^^^^^^^^^^^^^^
  File "/usr/lib/python3.12/concurrent/futures/thread.py", line 58, in run
    result = self.fn(*self.args, **self.kwargs)
             ^^^^^^^^^^^^^^^^^^^^^^^^^^^^^^^^^^
  File "/usr/lib/python3.12/socket.py", line 963, in getaddrinfo
    for res in _socket.getaddrinfo(host, port, family, type, proto, flags):
               ^^^^^^^^^^^^^^^^^^^^^^^^^^^^^^^^^^^^^^^^^^^^^^^^^^^^^^^^^^^
socket.gaierror: [Errno -3] Temporary failure in name resolution

The above exception was the direct cause of the following exception:

Traceback (most recent call last):
  File "/home/imafella/Documents/Development/discord_banker_bot/.venv/lib/python3.12/site-packages/discord/client.py", line 701, in connect
    self.ws = await asyncio.wait_for(coro, timeout=60.0)
              ^^^^^^^^^^^^^^^^^^^^^^^^^^^^^^^^^^^^^^^^^^
  File "/usr/lib/python3.12/asyncio/tasks.py", line 520, in wait_for
    return await fut
           ^^^^^^^^^
  File "/home/imafella/Documents/Development/discord_banker_bot/.venv/lib/python3.12/site-packages/discord/gateway.py", line 375, in from_client
    socket = await client.http.ws_connect(str(url))
             ^^^^^^^^^^^^^^^^^^^^^^^^^^^^^^^^^^^^^^
  File "/home/imafella/Documents/Development/discord_banker_bot/.venv/lib/python3.12/site-packages/discord/http.py", line 554, in ws_connect
    return await self.__session.ws_connect(url, **kwargs)
           ^^^^^^^^^^^^^^^^^^^^^^^^^^^^^^^^^^^^^^^^^^^^^^
  File "/home/imafella/Documents/Development/discord_banker_bot/.venv/lib/python3.12/site-packages/aiohttp/client.py", line 1036, in _ws_connect
    resp = await self.request(
           ^^^^^^^^^^^^^^^^^^^
  File "/home/imafella/Documents/Development/discord_banker_bot/.venv/lib/python3.12/site-packages/aiohttp/client.py", line 760, in _request
    resp = await handler(req)
           ^^^^^^^^^^^^^^^^^^
  File "/home/imafella/Documents/Development/discord_banker_bot/.venv/lib/python3.12/site-packages/aiohttp/client.py", line 715, in _connect_and_send_request
    conn = await self._connector.connect(
           ^^^^^^^^^^^^^^^^^^^^^^^^^^^^^^
  File "/home/imafella/Documents/Development/discord_banker_bot/.venv/lib/python3.12/site-packages/aiohttp/connector.py", line 561, in connect
    proto = await self._create_connection(req, traces, timeout)
            ^^^^^^^^^^^^^^^^^^^^^^^^^^^^^^^^^^^^^^^^^^^^^^^^^^^
  File "/home/imafella/Documents/Development/discord_banker_bot/.venv/lib/python3.12/site-packages/aiohttp/connector.py", line 1074, in _create_connection
    _, proto = await self._create_direct_connection(req, traces, timeout)
               ^^^^^^^^^^^^^^^^^^^^^^^^^^^^^^^^^^^^^^^^^^^^^^^^^^^^^^^^^^
  File "/home/imafella/Documents/Development/discord_banker_bot/.venv/lib/python3.12/site-packages/aiohttp/connector.py", line 1382, in _create_direct_connection
    raise ClientConnectorDNSError(req.connection_key, exc) from exc
aiohttp.client_exceptions.ClientConnectorDNSError: Cannot connect to host gateway-us-east1-b.discord.gg:443 ssl:default [Temporary failure in name resolution]
2025-06-10 04:04:53,939:ERROR:Attempting a reconnect in 3.11s
Traceback (most recent call last):
  File "/home/imafella/Documents/Development/discord_banker_bot/.venv/lib/python3.12/site-packages/aiohttp/connector.py", line 1376, in _create_direct_connection
    hosts = await self._resolve_host(host, port, traces=traces)
            ^^^^^^^^^^^^^^^^^^^^^^^^^^^^^^^^^^^^^^^^^^^^^^^^^^^
  File "/home/imafella/Documents/Development/discord_banker_bot/.venv/lib/python3.12/site-packages/aiohttp/connector.py", line 1013, in _resolve_host
    return await asyncio.shield(resolved_host_task)
           ^^^^^^^^^^^^^^^^^^^^^^^^^^^^^^^^^^^^^^^^
  File "/home/imafella/Documents/Development/discord_banker_bot/.venv/lib/python3.12/site-packages/aiohttp/connector.py", line 1044, in _resolve_host_with_throttle
    addrs = await self._resolver.resolve(host, port, family=self._family)
            ^^^^^^^^^^^^^^^^^^^^^^^^^^^^^^^^^^^^^^^^^^^^^^^^^^^^^^^^^^^^^
  File "/home/imafella/Documents/Development/discord_banker_bot/.venv/lib/python3.12/site-packages/aiohttp/resolver.py", line 40, in resolve
    infos = await self._loop.getaddrinfo(
            ^^^^^^^^^^^^^^^^^^^^^^^^^^^^^
  File "/usr/lib/python3.12/asyncio/base_events.py", line 901, in getaddrinfo
    return await self.run_in_executor(
           ^^^^^^^^^^^^^^^^^^^^^^^^^^^
  File "/usr/lib/python3.12/concurrent/futures/thread.py", line 58, in run
    result = self.fn(*self.args, **self.kwargs)
             ^^^^^^^^^^^^^^^^^^^^^^^^^^^^^^^^^^
  File "/usr/lib/python3.12/socket.py", line 963, in getaddrinfo
    for res in _socket.getaddrinfo(host, port, family, type, proto, flags):
               ^^^^^^^^^^^^^^^^^^^^^^^^^^^^^^^^^^^^^^^^^^^^^^^^^^^^^^^^^^^
socket.gaierror: [Errno -3] Temporary failure in name resolution

The above exception was the direct cause of the following exception:

Traceback (most recent call last):
  File "/home/imafella/Documents/Development/discord_banker_bot/.venv/lib/python3.12/site-packages/discord/client.py", line 701, in connect
    self.ws = await asyncio.wait_for(coro, timeout=60.0)
              ^^^^^^^^^^^^^^^^^^^^^^^^^^^^^^^^^^^^^^^^^^
  File "/usr/lib/python3.12/asyncio/tasks.py", line 520, in wait_for
    return await fut
           ^^^^^^^^^
  File "/home/imafella/Documents/Development/discord_banker_bot/.venv/lib/python3.12/site-packages/discord/gateway.py", line 375, in from_client
    socket = await client.http.ws_connect(str(url))
             ^^^^^^^^^^^^^^^^^^^^^^^^^^^^^^^^^^^^^^
  File "/home/imafella/Documents/Development/discord_banker_bot/.venv/lib/python3.12/site-packages/discord/http.py", line 554, in ws_connect
    return await self.__session.ws_connect(url, **kwargs)
           ^^^^^^^^^^^^^^^^^^^^^^^^^^^^^^^^^^^^^^^^^^^^^^
  File "/home/imafella/Documents/Development/discord_banker_bot/.venv/lib/python3.12/site-packages/aiohttp/client.py", line 1036, in _ws_connect
    resp = await self.request(
           ^^^^^^^^^^^^^^^^^^^
  File "/home/imafella/Documents/Development/discord_banker_bot/.venv/lib/python3.12/site-packages/aiohttp/client.py", line 760, in _request
    resp = await handler(req)
           ^^^^^^^^^^^^^^^^^^
  File "/home/imafella/Documents/Development/discord_banker_bot/.venv/lib/python3.12/site-packages/aiohttp/client.py", line 715, in _connect_and_send_request
    conn = await self._connector.connect(
           ^^^^^^^^^^^^^^^^^^^^^^^^^^^^^^
  File "/home/imafella/Documents/Development/discord_banker_bot/.venv/lib/python3.12/site-packages/aiohttp/connector.py", line 561, in connect
    proto = await self._create_connection(req, traces, timeout)
            ^^^^^^^^^^^^^^^^^^^^^^^^^^^^^^^^^^^^^^^^^^^^^^^^^^^
  File "/home/imafella/Documents/Development/discord_banker_bot/.venv/lib/python3.12/site-packages/aiohttp/connector.py", line 1074, in _create_connection
    _, proto = await self._create_direct_connection(req, traces, timeout)
               ^^^^^^^^^^^^^^^^^^^^^^^^^^^^^^^^^^^^^^^^^^^^^^^^^^^^^^^^^^
  File "/home/imafella/Documents/Development/discord_banker_bot/.venv/lib/python3.12/site-packages/aiohttp/connector.py", line 1382, in _create_direct_connection
    raise ClientConnectorDNSError(req.connection_key, exc) from exc
aiohttp.client_exceptions.ClientConnectorDNSError: Cannot connect to host gateway-us-east1-b.discord.gg:443 ssl:default [Temporary failure in name resolution]
2025-06-10 04:04:57,060:ERROR:Attempting a reconnect in 6.16s
Traceback (most recent call last):
  File "/home/imafella/Documents/Development/discord_banker_bot/.venv/lib/python3.12/site-packages/aiohttp/connector.py", line 1376, in _create_direct_connection
    hosts = await self._resolve_host(host, port, traces=traces)
            ^^^^^^^^^^^^^^^^^^^^^^^^^^^^^^^^^^^^^^^^^^^^^^^^^^^
  File "/home/imafella/Documents/Development/discord_banker_bot/.venv/lib/python3.12/site-packages/aiohttp/connector.py", line 1013, in _resolve_host
    return await asyncio.shield(resolved_host_task)
           ^^^^^^^^^^^^^^^^^^^^^^^^^^^^^^^^^^^^^^^^
  File "/home/imafella/Documents/Development/discord_banker_bot/.venv/lib/python3.12/site-packages/aiohttp/connector.py", line 1044, in _resolve_host_with_throttle
    addrs = await self._resolver.resolve(host, port, family=self._family)
            ^^^^^^^^^^^^^^^^^^^^^^^^^^^^^^^^^^^^^^^^^^^^^^^^^^^^^^^^^^^^^
  File "/home/imafella/Documents/Development/discord_banker_bot/.venv/lib/python3.12/site-packages/aiohttp/resolver.py", line 40, in resolve
    infos = await self._loop.getaddrinfo(
            ^^^^^^^^^^^^^^^^^^^^^^^^^^^^^
  File "/usr/lib/python3.12/asyncio/base_events.py", line 901, in getaddrinfo
    return await self.run_in_executor(
           ^^^^^^^^^^^^^^^^^^^^^^^^^^^
  File "/usr/lib/python3.12/concurrent/futures/thread.py", line 58, in run
    result = self.fn(*self.args, **self.kwargs)
             ^^^^^^^^^^^^^^^^^^^^^^^^^^^^^^^^^^
  File "/usr/lib/python3.12/socket.py", line 963, in getaddrinfo
    for res in _socket.getaddrinfo(host, port, family, type, proto, flags):
               ^^^^^^^^^^^^^^^^^^^^^^^^^^^^^^^^^^^^^^^^^^^^^^^^^^^^^^^^^^^
socket.gaierror: [Errno -3] Temporary failure in name resolution

The above exception was the direct cause of the following exception:

Traceback (most recent call last):
  File "/home/imafella/Documents/Development/discord_banker_bot/.venv/lib/python3.12/site-packages/discord/client.py", line 701, in connect
    self.ws = await asyncio.wait_for(coro, timeout=60.0)
              ^^^^^^^^^^^^^^^^^^^^^^^^^^^^^^^^^^^^^^^^^^
  File "/usr/lib/python3.12/asyncio/tasks.py", line 520, in wait_for
    return await fut
           ^^^^^^^^^
  File "/home/imafella/Documents/Development/discord_banker_bot/.venv/lib/python3.12/site-packages/discord/gateway.py", line 375, in from_client
    socket = await client.http.ws_connect(str(url))
             ^^^^^^^^^^^^^^^^^^^^^^^^^^^^^^^^^^^^^^
  File "/home/imafella/Documents/Development/discord_banker_bot/.venv/lib/python3.12/site-packages/discord/http.py", line 554, in ws_connect
    return await self.__session.ws_connect(url, **kwargs)
           ^^^^^^^^^^^^^^^^^^^^^^^^^^^^^^^^^^^^^^^^^^^^^^
  File "/home/imafella/Documents/Development/discord_banker_bot/.venv/lib/python3.12/site-packages/aiohttp/client.py", line 1036, in _ws_connect
    resp = await self.request(
           ^^^^^^^^^^^^^^^^^^^
  File "/home/imafella/Documents/Development/discord_banker_bot/.venv/lib/python3.12/site-packages/aiohttp/client.py", line 760, in _request
    resp = await handler(req)
           ^^^^^^^^^^^^^^^^^^
  File "/home/imafella/Documents/Development/discord_banker_bot/.venv/lib/python3.12/site-packages/aiohttp/client.py", line 715, in _connect_and_send_request
    conn = await self._connector.connect(
           ^^^^^^^^^^^^^^^^^^^^^^^^^^^^^^
  File "/home/imafella/Documents/Development/discord_banker_bot/.venv/lib/python3.12/site-packages/aiohttp/connector.py", line 561, in connect
    proto = await self._create_connection(req, traces, timeout)
            ^^^^^^^^^^^^^^^^^^^^^^^^^^^^^^^^^^^^^^^^^^^^^^^^^^^
  File "/home/imafella/Documents/Development/discord_banker_bot/.venv/lib/python3.12/site-packages/aiohttp/connector.py", line 1074, in _create_connection
    _, proto = await self._create_direct_connection(req, traces, timeout)
               ^^^^^^^^^^^^^^^^^^^^^^^^^^^^^^^^^^^^^^^^^^^^^^^^^^^^^^^^^^
  File "/home/imafella/Documents/Development/discord_banker_bot/.venv/lib/python3.12/site-packages/aiohttp/connector.py", line 1382, in _create_direct_connection
    raise ClientConnectorDNSError(req.connection_key, exc) from exc
aiohttp.client_exceptions.ClientConnectorDNSError: Cannot connect to host gateway-us-east1-b.discord.gg:443 ssl:default [Temporary failure in name resolution]
2025-06-10 04:05:03,229:ERROR:Attempting a reconnect in 19.08s
Traceback (most recent call last):
  File "/home/imafella/Documents/Development/discord_banker_bot/.venv/lib/python3.12/site-packages/aiohttp/connector.py", line 1376, in _create_direct_connection
    hosts = await self._resolve_host(host, port, traces=traces)
            ^^^^^^^^^^^^^^^^^^^^^^^^^^^^^^^^^^^^^^^^^^^^^^^^^^^
  File "/home/imafella/Documents/Development/discord_banker_bot/.venv/lib/python3.12/site-packages/aiohttp/connector.py", line 1013, in _resolve_host
    return await asyncio.shield(resolved_host_task)
           ^^^^^^^^^^^^^^^^^^^^^^^^^^^^^^^^^^^^^^^^
  File "/home/imafella/Documents/Development/discord_banker_bot/.venv/lib/python3.12/site-packages/aiohttp/connector.py", line 1044, in _resolve_host_with_throttle
    addrs = await self._resolver.resolve(host, port, family=self._family)
            ^^^^^^^^^^^^^^^^^^^^^^^^^^^^^^^^^^^^^^^^^^^^^^^^^^^^^^^^^^^^^
  File "/home/imafella/Documents/Development/discord_banker_bot/.venv/lib/python3.12/site-packages/aiohttp/resolver.py", line 40, in resolve
    infos = await self._loop.getaddrinfo(
            ^^^^^^^^^^^^^^^^^^^^^^^^^^^^^
  File "/usr/lib/python3.12/asyncio/base_events.py", line 901, in getaddrinfo
    return await self.run_in_executor(
           ^^^^^^^^^^^^^^^^^^^^^^^^^^^
  File "/usr/lib/python3.12/concurrent/futures/thread.py", line 58, in run
    result = self.fn(*self.args, **self.kwargs)
             ^^^^^^^^^^^^^^^^^^^^^^^^^^^^^^^^^^
  File "/usr/lib/python3.12/socket.py", line 963, in getaddrinfo
    for res in _socket.getaddrinfo(host, port, family, type, proto, flags):
               ^^^^^^^^^^^^^^^^^^^^^^^^^^^^^^^^^^^^^^^^^^^^^^^^^^^^^^^^^^^
socket.gaierror: [Errno -3] Temporary failure in name resolution

The above exception was the direct cause of the following exception:

Traceback (most recent call last):
  File "/home/imafella/Documents/Development/discord_banker_bot/.venv/lib/python3.12/site-packages/discord/client.py", line 701, in connect
    self.ws = await asyncio.wait_for(coro, timeout=60.0)
              ^^^^^^^^^^^^^^^^^^^^^^^^^^^^^^^^^^^^^^^^^^
  File "/usr/lib/python3.12/asyncio/tasks.py", line 520, in wait_for
    return await fut
           ^^^^^^^^^
  File "/home/imafella/Documents/Development/discord_banker_bot/.venv/lib/python3.12/site-packages/discord/gateway.py", line 375, in from_client
    socket = await client.http.ws_connect(str(url))
             ^^^^^^^^^^^^^^^^^^^^^^^^^^^^^^^^^^^^^^
  File "/home/imafella/Documents/Development/discord_banker_bot/.venv/lib/python3.12/site-packages/discord/http.py", line 554, in ws_connect
    return await self.__session.ws_connect(url, **kwargs)
           ^^^^^^^^^^^^^^^^^^^^^^^^^^^^^^^^^^^^^^^^^^^^^^
  File "/home/imafella/Documents/Development/discord_banker_bot/.venv/lib/python3.12/site-packages/aiohttp/client.py", line 1036, in _ws_connect
    resp = await self.request(
           ^^^^^^^^^^^^^^^^^^^
  File "/home/imafella/Documents/Development/discord_banker_bot/.venv/lib/python3.12/site-packages/aiohttp/client.py", line 760, in _request
    resp = await handler(req)
           ^^^^^^^^^^^^^^^^^^
  File "/home/imafella/Documents/Development/discord_banker_bot/.venv/lib/python3.12/site-packages/aiohttp/client.py", line 715, in _connect_and_send_request
    conn = await self._connector.connect(
           ^^^^^^^^^^^^^^^^^^^^^^^^^^^^^^
  File "/home/imafella/Documents/Development/discord_banker_bot/.venv/lib/python3.12/site-packages/aiohttp/connector.py", line 561, in connect
    proto = await self._create_connection(req, traces, timeout)
            ^^^^^^^^^^^^^^^^^^^^^^^^^^^^^^^^^^^^^^^^^^^^^^^^^^^
  File "/home/imafella/Documents/Development/discord_banker_bot/.venv/lib/python3.12/site-packages/aiohttp/connector.py", line 1074, in _create_connection
    _, proto = await self._create_direct_connection(req, traces, timeout)
               ^^^^^^^^^^^^^^^^^^^^^^^^^^^^^^^^^^^^^^^^^^^^^^^^^^^^^^^^^^
  File "/home/imafella/Documents/Development/discord_banker_bot/.venv/lib/python3.12/site-packages/aiohttp/connector.py", line 1382, in _create_direct_connection
    raise ClientConnectorDNSError(req.connection_key, exc) from exc
aiohttp.client_exceptions.ClientConnectorDNSError: Cannot connect to host gateway-us-east1-b.discord.gg:443 ssl:default [Temporary failure in name resolution]
2025-06-10 04:05:22,326:ERROR:Attempting a reconnect in 52.32s
Traceback (most recent call last):
  File "/home/imafella/Documents/Development/discord_banker_bot/.venv/lib/python3.12/site-packages/aiohttp/connector.py", line 1376, in _create_direct_connection
    hosts = await self._resolve_host(host, port, traces=traces)
            ^^^^^^^^^^^^^^^^^^^^^^^^^^^^^^^^^^^^^^^^^^^^^^^^^^^
  File "/home/imafella/Documents/Development/discord_banker_bot/.venv/lib/python3.12/site-packages/aiohttp/connector.py", line 1013, in _resolve_host
    return await asyncio.shield(resolved_host_task)
           ^^^^^^^^^^^^^^^^^^^^^^^^^^^^^^^^^^^^^^^^
  File "/home/imafella/Documents/Development/discord_banker_bot/.venv/lib/python3.12/site-packages/aiohttp/connector.py", line 1044, in _resolve_host_with_throttle
    addrs = await self._resolver.resolve(host, port, family=self._family)
            ^^^^^^^^^^^^^^^^^^^^^^^^^^^^^^^^^^^^^^^^^^^^^^^^^^^^^^^^^^^^^
  File "/home/imafella/Documents/Development/discord_banker_bot/.venv/lib/python3.12/site-packages/aiohttp/resolver.py", line 40, in resolve
    infos = await self._loop.getaddrinfo(
            ^^^^^^^^^^^^^^^^^^^^^^^^^^^^^
  File "/usr/lib/python3.12/asyncio/base_events.py", line 901, in getaddrinfo
    return await self.run_in_executor(
           ^^^^^^^^^^^^^^^^^^^^^^^^^^^
  File "/usr/lib/python3.12/concurrent/futures/thread.py", line 58, in run
    result = self.fn(*self.args, **self.kwargs)
             ^^^^^^^^^^^^^^^^^^^^^^^^^^^^^^^^^^
  File "/usr/lib/python3.12/socket.py", line 963, in getaddrinfo
    for res in _socket.getaddrinfo(host, port, family, type, proto, flags):
               ^^^^^^^^^^^^^^^^^^^^^^^^^^^^^^^^^^^^^^^^^^^^^^^^^^^^^^^^^^^
socket.gaierror: [Errno -3] Temporary failure in name resolution

The above exception was the direct cause of the following exception:

Traceback (most recent call last):
  File "/home/imafella/Documents/Development/discord_banker_bot/.venv/lib/python3.12/site-packages/discord/client.py", line 701, in connect
    self.ws = await asyncio.wait_for(coro, timeout=60.0)
              ^^^^^^^^^^^^^^^^^^^^^^^^^^^^^^^^^^^^^^^^^^
  File "/usr/lib/python3.12/asyncio/tasks.py", line 520, in wait_for
    return await fut
           ^^^^^^^^^
  File "/home/imafella/Documents/Development/discord_banker_bot/.venv/lib/python3.12/site-packages/discord/gateway.py", line 375, in from_client
    socket = await client.http.ws_connect(str(url))
             ^^^^^^^^^^^^^^^^^^^^^^^^^^^^^^^^^^^^^^
  File "/home/imafella/Documents/Development/discord_banker_bot/.venv/lib/python3.12/site-packages/discord/http.py", line 554, in ws_connect
    return await self.__session.ws_connect(url, **kwargs)
           ^^^^^^^^^^^^^^^^^^^^^^^^^^^^^^^^^^^^^^^^^^^^^^
  File "/home/imafella/Documents/Development/discord_banker_bot/.venv/lib/python3.12/site-packages/aiohttp/client.py", line 1036, in _ws_connect
    resp = await self.request(
           ^^^^^^^^^^^^^^^^^^^
  File "/home/imafella/Documents/Development/discord_banker_bot/.venv/lib/python3.12/site-packages/aiohttp/client.py", line 760, in _request
    resp = await handler(req)
           ^^^^^^^^^^^^^^^^^^
  File "/home/imafella/Documents/Development/discord_banker_bot/.venv/lib/python3.12/site-packages/aiohttp/client.py", line 715, in _connect_and_send_request
    conn = await self._connector.connect(
           ^^^^^^^^^^^^^^^^^^^^^^^^^^^^^^
  File "/home/imafella/Documents/Development/discord_banker_bot/.venv/lib/python3.12/site-packages/aiohttp/connector.py", line 561, in connect
    proto = await self._create_connection(req, traces, timeout)
            ^^^^^^^^^^^^^^^^^^^^^^^^^^^^^^^^^^^^^^^^^^^^^^^^^^^
  File "/home/imafella/Documents/Development/discord_banker_bot/.venv/lib/python3.12/site-packages/aiohttp/connector.py", line 1074, in _create_connection
    _, proto = await self._create_direct_connection(req, traces, timeout)
               ^^^^^^^^^^^^^^^^^^^^^^^^^^^^^^^^^^^^^^^^^^^^^^^^^^^^^^^^^^
  File "/home/imafella/Documents/Development/discord_banker_bot/.venv/lib/python3.12/site-packages/aiohttp/connector.py", line 1382, in _create_direct_connection
    raise ClientConnectorDNSError(req.connection_key, exc) from exc
aiohttp.client_exceptions.ClientConnectorDNSError: Cannot connect to host gateway-us-east1-b.discord.gg:443 ssl:default [Temporary failure in name resolution]
2025-06-10 04:06:14,660:ERROR:Attempting a reconnect in 70.19s
Traceback (most recent call last):
  File "/home/imafella/Documents/Development/discord_banker_bot/.venv/lib/python3.12/site-packages/aiohttp/connector.py", line 1376, in _create_direct_connection
    hosts = await self._resolve_host(host, port, traces=traces)
            ^^^^^^^^^^^^^^^^^^^^^^^^^^^^^^^^^^^^^^^^^^^^^^^^^^^
  File "/home/imafella/Documents/Development/discord_banker_bot/.venv/lib/python3.12/site-packages/aiohttp/connector.py", line 1013, in _resolve_host
    return await asyncio.shield(resolved_host_task)
           ^^^^^^^^^^^^^^^^^^^^^^^^^^^^^^^^^^^^^^^^
  File "/home/imafella/Documents/Development/discord_banker_bot/.venv/lib/python3.12/site-packages/aiohttp/connector.py", line 1044, in _resolve_host_with_throttle
    addrs = await self._resolver.resolve(host, port, family=self._family)
            ^^^^^^^^^^^^^^^^^^^^^^^^^^^^^^^^^^^^^^^^^^^^^^^^^^^^^^^^^^^^^
  File "/home/imafella/Documents/Development/discord_banker_bot/.venv/lib/python3.12/site-packages/aiohttp/resolver.py", line 40, in resolve
    infos = await self._loop.getaddrinfo(
            ^^^^^^^^^^^^^^^^^^^^^^^^^^^^^
  File "/usr/lib/python3.12/asyncio/base_events.py", line 901, in getaddrinfo
    return await self.run_in_executor(
           ^^^^^^^^^^^^^^^^^^^^^^^^^^^
  File "/usr/lib/python3.12/concurrent/futures/thread.py", line 58, in run
    result = self.fn(*self.args, **self.kwargs)
             ^^^^^^^^^^^^^^^^^^^^^^^^^^^^^^^^^^
  File "/usr/lib/python3.12/socket.py", line 963, in getaddrinfo
    for res in _socket.getaddrinfo(host, port, family, type, proto, flags):
               ^^^^^^^^^^^^^^^^^^^^^^^^^^^^^^^^^^^^^^^^^^^^^^^^^^^^^^^^^^^
socket.gaierror: [Errno -3] Temporary failure in name resolution

The above exception was the direct cause of the following exception:

Traceback (most recent call last):
  File "/home/imafella/Documents/Development/discord_banker_bot/.venv/lib/python3.12/site-packages/discord/client.py", line 701, in connect
    self.ws = await asyncio.wait_for(coro, timeout=60.0)
              ^^^^^^^^^^^^^^^^^^^^^^^^^^^^^^^^^^^^^^^^^^
  File "/usr/lib/python3.12/asyncio/tasks.py", line 520, in wait_for
    return await fut
           ^^^^^^^^^
  File "/home/imafella/Documents/Development/discord_banker_bot/.venv/lib/python3.12/site-packages/discord/gateway.py", line 375, in from_client
    socket = await client.http.ws_connect(str(url))
             ^^^^^^^^^^^^^^^^^^^^^^^^^^^^^^^^^^^^^^
  File "/home/imafella/Documents/Development/discord_banker_bot/.venv/lib/python3.12/site-packages/discord/http.py", line 554, in ws_connect
    return await self.__session.ws_connect(url, **kwargs)
           ^^^^^^^^^^^^^^^^^^^^^^^^^^^^^^^^^^^^^^^^^^^^^^
  File "/home/imafella/Documents/Development/discord_banker_bot/.venv/lib/python3.12/site-packages/aiohttp/client.py", line 1036, in _ws_connect
    resp = await self.request(
           ^^^^^^^^^^^^^^^^^^^
  File "/home/imafella/Documents/Development/discord_banker_bot/.venv/lib/python3.12/site-packages/aiohttp/client.py", line 760, in _request
    resp = await handler(req)
           ^^^^^^^^^^^^^^^^^^
  File "/home/imafella/Documents/Development/discord_banker_bot/.venv/lib/python3.12/site-packages/aiohttp/client.py", line 715, in _connect_and_send_request
    conn = await self._connector.connect(
           ^^^^^^^^^^^^^^^^^^^^^^^^^^^^^^
  File "/home/imafella/Documents/Development/discord_banker_bot/.venv/lib/python3.12/site-packages/aiohttp/connector.py", line 561, in connect
    proto = await self._create_connection(req, traces, timeout)
            ^^^^^^^^^^^^^^^^^^^^^^^^^^^^^^^^^^^^^^^^^^^^^^^^^^^
  File "/home/imafella/Documents/Development/discord_banker_bot/.venv/lib/python3.12/site-packages/aiohttp/connector.py", line 1074, in _create_connection
    _, proto = await self._create_direct_connection(req, traces, timeout)
               ^^^^^^^^^^^^^^^^^^^^^^^^^^^^^^^^^^^^^^^^^^^^^^^^^^^^^^^^^^
  File "/home/imafella/Documents/Development/discord_banker_bot/.venv/lib/python3.12/site-packages/aiohttp/connector.py", line 1382, in _create_direct_connection
    raise ClientConnectorDNSError(req.connection_key, exc) from exc
aiohttp.client_exceptions.ClientConnectorDNSError: Cannot connect to host gateway-us-east1-b.discord.gg:443 ssl:default [Temporary failure in name resolution]
2025-06-10 04:07:25,108:INFO:Shard ID None session has been invalidated.
2025-06-10 04:07:30,484:INFO:Shard ID None has connected to Gateway (Session ID: 29f40f2efc5151e6217c432833619874).
2025-06-10 04:45:42,128:INFO:Shard ID None has successfully RESUMED session 29f40f2efc5151e6217c432833619874.
2025-06-10 06:46:19,698:INFO:Shard ID None has successfully RESUMED session 29f40f2efc5151e6217c432833619874.
2025-06-10 09:22:04,146:INFO:Shard ID None has successfully RESUMED session 29f40f2efc5151e6217c432833619874.
